Workbook

Sheet 模板
A1: 门店+姓名 | B1: 门店 | C1: 岗位 | D1: 姓名 | E1: 员工状态 | F1: 报税工资 | G1: 个税 | H1: 基本养老保险费 | I1: 基本医疗保险费 | J1: 失业保险费 | K1: 分公司 | L1: 身份证号 | M1: 联系方式 | N1: 实际个税 | O1: 备注 | Q1: 差额 | S1: 差额1
D2: 刘甜甜 | F2: 17000 | G2: 655.02 | H2: 1360 | I2: 347 | J2: 51 | K2: 武汉山道 | L2: 420684198505276040
D3: 杨艳 | F3: 2000 | H3: 359.84 | I3: 96.96 | J3: 13.49 | K3: 武汉山道 | L3: 420623198201201047
D4: 刘建斌 | F4: 17000 | G4: 655.02 | H4: 1360 | I4: 347 | J4: 51 | K4: 武汉山道 | L4: 420684198402276056 | M4: 15927000009

Sheet 1月
A1: 门店+姓名 | B1: 门店 | C1: 岗位 | D1: 姓名 | E1: 员工状态 | F1: 报税工资 | G1: 个税 | H1: 分公司 | I1: 身份证号 | J1: 联系方式 | K1: 实际个税 | L1: 备注 | N1: 差额 | P1: 差额1
D2: 刘甜甜 | F2: 17000 | G2: 360 | H2: 武汉山道 | I2: 420684198505276040 | K2: 360 | N2: =G2-K2 -> 0
D3: 杨艳 | F3: 2000 | G3: 0 | H3: 武汉山道 | I3: 420623198201201047 | K3: 0 | N3: =G3-K3 -> 0
D4: 刘建斌 | F4: 17000 | G4: 240 | H4: 武汉山道 | I4: 420684198402276056 | K4: 240 | N4: =G4-K4 -> 0
A5: 蚌埠吾悦店王格 | B5: 蚌埠吾悦店 | C5: 前台主管 | D5: 王格 | E5: 在职 | F5: 3950 | G5: 0 | H5: =VLOOKUP(A5,'[1]12月'!$A:$H,8,FALSE) -> 朝晖人力 | I5: =VLOOKUP(A5,'[1]12月'!$A:$I,9,FALSE) -> 340322200502054623 | J5: =VLOOKUP(A5,'[1]12月'!$A:$J,10,FALSE) -> 15375468652 | K5: 0 | N5: =G5-K5 -> 0
A6: 蚌埠吾悦店薛艺 | B6: 蚌埠吾悦店 | C6: 前台 | D6: 薛艺 | E6: 离职 | F6: 288.46 | G6: 0 | H6: =VLOOKUP(A6,'[1]12月'!$A:$H,8,FALSE) -> 朝晖人力 | I6: =VLOOKUP(A6,'[1]12月'!$A:$I,9,FALSE) -> 340304200306130649 | J6: =VLOOKUP(A6,'[1]12月'!$A:$J,10,FALSE) -> 15255282978 | K6: 0 | N6: =G6-K6 -> 0
A7: 蚌埠吾悦店李响 | B7: 蚌埠吾悦店 | C7: 前台 | D7: 李响 | E7: 在职 | F7: 2500 | G7: 0 | H7: 朝晖人力 | I7: =VLOOKUP(A7,[2]在职名单!$D:$AE,28,FALSE) -> 34030219860130002X | J7: =VLOOKUP(A7,[2]在职名单!$D:$AJ,33,FALSE) -> 0 | K7: 0 | N7: =G7-K7 -> 0
A8: 蚌埠吾悦店赵红 | B8: 蚌埠吾悦店 | C8: 保洁 | D8: 赵红 | E8: 在职 | F8: 2390 | G8: 0 | H8: 朝晖人力 | I8: =VLOOKUP(A8,'[1]12月'!$A:$I,9,FALSE) -> 340302197012310428 | J8: =VLOOKUP(A8,'[1]12月'!$A:$J,10,FALSE) -> 16655298121 | K8: 0 | N8: =G8-K8 -> 0
A9: 蚌埠吾悦店陆春亮 | B9: 蚌埠吾悦店 | C9: 保洁 | D9: 陆春亮 | E9: 在职 | F9: 2390 | G9: 0 | H9: 朝晖人力 | I9: =VLOOKUP(A9,'[1]12月'!$A:$I,9,FALSE) -> 340302196303260411 | J9: =VLOOKUP(A9,'[1]12月'!$A:$J,10,FALSE) -> 13093664952 | K9: 0 | N9: =G9-K9 -> 0
A10: 蚌埠吾悦店万小建 | B10: 蚌埠吾悦店 | C10: 会籍经理 | D10: 万小建 | E10: 在职 | F10: 5531.4395 | G10: 0 | H10: 朝晖人力 | I10: =VLOOKUP(A10,'[1]12月'!$A:$I,9,FALSE) -> 340321198606010899 | J10: =VLOOKUP(A10,'[1]12月'!$A:$J,10,FALSE) -> 1396528/6269 | K10: 0 | N10: =G10-K10 -> 0
A11: 蚌埠吾悦店邵家文 | B11: 蚌埠吾悦店 | C11: 会籍 | D11: 邵家文 | E11: 在职 | F11: 2765.236 | G11: 0 | H11: 朝晖人力 | I11: =VLOOKUP(A11,'[1]12月'!$A:$I,9,FALSE) -> 340321200412065031 | J11: =VLOOKUP(A11,'[1]12月'!$A:$J,10,FALSE) -> 17201600134 | K11: 0 | N11: =G11-K11 -> 0
A12: 蚌埠吾悦店赵惠春 | B12: 蚌埠吾悦店 | C12: 会籍 | D12: 赵惠春 | E12: 在职 | F12: 3611.92 | G12: 0 | H12: 朝晖人力 | I12: =VLOOKUP(A12,'[1]12月'!$A:$I,9,FALSE) -> 370406200602046621 | J12: =VLOOKUP(A12,'[1]12月'!$A:$J,10,FALSE) -> 19055243298 | K12: 0 | N12: =G12-K12 -> 0
A13: 蚌埠吾悦店曹泽 | B13: 蚌埠吾悦店 | C13: 会籍 | D13: 曹泽 | E13: 离职 | F13: 1501.44 | G13: 0 | H13: 朝晖人力 | I13: =VLOOKUP(A13,'[1]12月'!$A:$I,9,FALSE) -> 340323200404246919 | J13: =VLOOKUP(A13,'[1]12月'!$A:$J,10,FALSE) -> 19556139314 | K13: 0 | N13: =G13-K13 -> 0
A14: 蚌埠吾悦店刘庆康 | B14: 蚌埠吾悦店 | C14: 会籍 | D14: 刘庆康 | E14: 在职 | F14: 2428.464 | G14: 0 | H14: 朝晖人力 | I14: =VLOOKUP(A14,[2]在职名单!$D:$AE,28,FALSE) -> 340302200512121011 | J14: =VLOOKUP(A14,[2]在职名单!$D:$AJ,33,FALSE) -> 0 | K14: 0 | N14: =G14-K14 -> 0
A15: 蚌埠吾悦店蒋维月 | B15: 蚌埠吾悦店 | C15: 会籍 | D15: 蒋维月 | E15: 在职 | F15: 1988.9108 | G15: 0 | H15: 朝晖人力 | I15: 340322200712043869 | J15: =VLOOKUP(A15,[2]在职名单!$D:$AJ,33,FALSE) -> 18714837986 | K15: 0 | N15: =G15-K15 -> 0
A16: 蚌埠吾悦店刘备 | B16: 蚌埠吾悦店 | C16: 私教经理 | D16: 刘备 | E16: 离职 | F16: 919.5045 | G16: 0 | H16: =VLOOKUP(A16,'[1]12月'!$A:$H,8,FALSE) -> 不报 | I16: =VLOOKUP(A16,'[1]12月'!$A:$I,9,FALSE) -> 340321199403172454 | J16: =VLOOKUP(A16,'[1]12月'!$A:$J,10,FALSE) -> 15555536558 | N16: =G16-K16 -> 0
A17: 蚌埠吾悦店韦云 | B17: 蚌埠吾悦店 | C17: 私教 | D17: 韦云 | E17: 在职 | F17: 1667.3318 | G17: 0 | H17: =VLOOKUP(A17,'[1]12月'!$A:$H,8,FALSE) -> 朝晖人力 | I17: =VLOOKUP(A17,'[1]12月'!$A:$I,9,FALSE) -> 340321200008202145 | J17: =VLOOKUP(A17,'[1]12月'!$A:$J,10,FALSE) -> 15755244417 | K17: 0 | N17: =G17-K17 -> 0
A18: 蚌埠吾悦店栾金良 | B18: 蚌埠吾悦店 | C18: 私教经理 | D18: 栾金良 | E18: 在职 | F18: 8230.0058 | G18: 323.01 | H18: =VLOOKUP(A18,'[1]12月'!$A:$H,8,FALSE) -> 朝晖人力 | I18: =VLOOKUP(A18,'[1]12月'!$A:$I,9,FALSE) -> 321302198506180055 | J18: =VLOOKUP(A18,'[1]12月'!$A:$J,10,FALSE) -> 13815786616 | K18: 323 | N18: =G18-K18 -> 0.01
A19: 蚌埠吾悦店曲蓝鹤 | B19: 蚌埠吾悦店 | C19: 私教 | D19: 曲蓝鹤 | E19: 在职 | F19: 606.11865 | G19: 0 | H19: 朝晖人力 | I19: =VLOOKUP(A19,[2]在职名单!$D:$AE,28,FALSE) -> 230505199011080214 | J19: =VLOOKUP(A19,[2]在职名单!$D:$AJ,33,FALSE) -> 17755263617 | K19: 0 | N19: =G19-K19 -> 0
A20: 蚌埠吾悦店林康 | B20: 蚌埠吾悦店 | C20: 泳教主管 | D20: 林康 | E20: 在职 | F20: 3901.2 | G20: 0 | H20: 朝晖人力 | I20: =VLOOKUP(A20,'[1]12月'!$A:$I,9,FALSE) -> 340321200212060850 | J20: =VLOOKUP(A20,'[1]12月'!$A:$J,10,FALSE) -> 15056356955 | K20: 0 | N20: =G20-K20 -> 0
A21: 蚌埠吾悦店周凯乐 | B21: 蚌埠吾悦店 | C21: 泳教 | D21: 周凯乐 | E21: 离职 | F21: 353.85 | G21: 0 | H21: 朝晖人力 | I21: =VLOOKUP(A21,[2]在职名单!$D:$AE,28,FALSE) -> 340321200108182495 | J21: =VLOOKUP(A21,[2]在职名单!$D:$AJ,33,FALSE) -> 18715261682 | K21: 0 | N21: =G21-K21 -> 0
A22: 蚌埠吾悦店曹芷莹 | B22: 蚌埠吾悦店 | C22: 安全员 | D22: 曹芷莹 | E22: 离职 | F22: 884.62 | G22: 0 | H22: =VLOOKUP(A22,'[1]12月'!$A:$H,8,FALSE) -> 朝晖人力 | I22: =VLOOKUP(A22,'[1]12月'!$A:$I,9,FALSE) -> 340323200802166965 | J22: =VLOOKUP(A22,'[1]12月'!$A:$J,10,FALSE) -> 15155224390 | K22: 0 | N22: =G22-K22 -> 0
A23: 蚌埠银泰店彭莹莹 | B23: 蚌埠银泰店 | C23: 前台主管 | D23: 彭莹莹 | E23: 在职 | F23: 3390 | G23: 0 | H23: =VLOOKUP(A23,'[1]12月'!$A:$H,8,FALSE) -> 朝晖人力 | I23: =VLOOKUP(A23,'[1]12月'!$A:$I,9,FALSE) -> 34031119930320142X | J23: =VLOOKUP(A23,'[1]12月'!$A:$J,10,FALSE) -> 18895657368 | K23: 0 | N23: =G23-K23 -> 0
A24: 蚌埠银泰店田雨鑫 | B24: 蚌埠银泰店 | C24: 前台 | D24: 田雨鑫 | E24: 离职 | F24: 393.85 | G24: 0 | H24: =VLOOKUP(A24,'[1]12月'!$A:$H,8,FALSE) -> 朝晖人力 | I24: =VLOOKUP(A24,'[1]12月'!$A:$I,9,FALSE) -> 341282200503124621 | J24: =VLOOKUP(A24,'[1]12月'!$A:$J,10,FALSE) -> 13696683639 | K24: 0 | N24: =G24-K24 -> 0
A25: 蚌埠银泰店沈诗玉 | B25: 蚌埠银泰店 | C25: 前台 | D25: 沈诗玉 | E25: 离职 | F25: 2405.77 | G25: 0 | H25: =VLOOKUP(A25,'[1]12月'!$A:$H,8,FALSE) -> 朝晖人力 | I25: =VLOOKUP(A25,'[1]12月'!$A:$I,9,FALSE) -> 340321199808313104 | J25: =VLOOKUP(A25,'[1]12月'!$A:$J,10,FALSE) -> 18096548666 | K25: 0 | N25: =G25-K25 -> 0
A26: 蚌埠银泰店钱晴 | B26: 蚌埠银泰店 | C26: 前台 | D26: 钱晴 | E26: 离职 | F26: 1483.4569 | G26: 0 | H26: 朝晖人力 | I26: =VLOOKUP(A26,[2]在职名单!$D:$AE,28,FALSE) -> 340311200011021625 | J26: =VLOOKUP(A26,[2]在职名单!$D:$AJ,33,FALSE) -> 0 | K26: 0 | N26: =G26-K26 -> 0
A27: 蚌埠银泰店王秉江 | B27: 蚌埠银泰店 | C27: 保洁 | D27: 王秉江 | E27: 离职 | F27: 796.15 | G27: 0 | H27: =VLOOKUP(A27,'[1]12月'!$A:$H,8,FALSE) -> 朝晖人力 | I27: =VLOOKUP(A27,'[1]12月'!$A:$I,9,FALSE) -> 340304195704070430 | J27: =VLOOKUP(A27,'[1]12月'!$A:$J,10,FALSE) -> 18655224998 | K27: 0 | N27: =G27-K27 -> 0
A28: 蚌埠银泰店李桂华 | B28: 蚌埠银泰店 | C28: 保洁 | D28: 李桂华 | E28: 在职 | F28: 2500 | G28: 0 | H28: =VLOOKUP(A28,'[1]12月'!$A:$H,8,FALSE) -> 朝晖人力 | I28: =VLOOKUP(A28,'[1]12月'!$A:$I,9,FALSE) -> 340123196511187707 | J28: =VLOOKUP(A28,'[1]12月'!$A:$J,10,FALSE) -> 17705522172 | K28: 0 | N28: =G28-K28 -> 0
A29: 蚌埠银泰店沈智淮 | B29: 蚌埠银泰店 | C29: 保洁 | D29: 沈智淮 | E29: 在职 | F29: 1661.5415 | G29: 0 | H29: 不报 | I29: =VLOOKUP(A29,[2]在职名单!$D:$AE,28,FALSE) -> 340302195510010496 | J29: =VLOOKUP(A29,[2]在职名单!$D:$AJ,33,FALSE) -> 18109655880 | N29: =G29-K29 -> 0
A30: 蚌埠银泰店王紫贵 | B30: 蚌埠银泰店 | C30: 会籍 | D30: 王紫贵 | E30: 在职 | F30: 4199.15 | G30: 0 | H30: =VLOOKUP(A30,'[1]12月'!$A:$H,8,FALSE) -> 朝晖人力 | I30: =VLOOKUP(A30,'[1]12月'!$A:$I,9,FALSE) -> 340303200302060616 | J30: =VLOOKUP(A30,'[1]12月'!$A:$J,10,FALSE) -> 18255215140 | K30: 0 | N30: =G30-K30 -> 0
A31: 蚌埠银泰店蔡龙飞 | B31: 蚌埠银泰店 | C31: 会籍 | D31: 蔡龙飞 | E31: 离职 | F31: 1748.58 | G31: 0 | H31: 朝晖人力 | I31: 340321199303101253 | J31: =VLOOKUP(A31,[2]在职名单!$D:$AJ,33,FALSE) -> 0 | K31: 0 | N31: =G31-K31 -> 0
A32: 蚌埠银泰店史玲娟 | B32: 蚌埠银泰店 | C32: 会籍 | D32: 史玲娟 | E32: 在职 | F32: 5792.05 | G32: 0 | H32: =VLOOKUP(A32,'[1]12月'!$A:$H,8,FALSE) -> 朝晖人力 | I32: =VLOOKUP(A32,'[1]12月'!$A:$I,9,FALSE) -> 340323200311216227 | J32: =VLOOKUP(A32,'[1]12月'!$A:$J,10,FALSE) -> 15755212422 | K32: 0 | N32: =G32-K32 -> 0
A33: 蚌埠银泰店张鑫杰 | B33: 蚌埠银泰店 | C33: 会籍 | D33: 张鑫杰 | E33: 在职 | F33: 4032.7 | G33: 0 | H33: 朝晖人力 | I33: 410221200502176512 | J33: 18836866156 | K33: 0 | N33: =G33-K33 -> 0
A34: 蚌埠银泰店孙齐云 | B34: 蚌埠银泰店 | C34: 私教经理 | D34: 孙齐云 | E34: 在职 | F34: 6231.0879 | G34: 36.93 | H34: 朝晖人力 | I34: =VLOOKUP(A34,[2]在职名单!$D:$AE,28,FALSE) -> 342626199407204919 | J34: =VLOOKUP(A34,[2]在职名单!$D:$AJ,33,FALSE) -> 13851536096 | K34: 36.93 | N34: =G34-K34 -> 0
A35: 蚌埠银泰店王世俊 | B35: 蚌埠银泰店 | C35: 私教 | D35: 王世俊 | E35: 离职 | F35: 1711.791 | G35: 0 | H35: =VLOOKUP(A35,'[1]12月'!$A:$H,8,FALSE) -> 朝晖人力 | I35: =VLOOKUP(A35,'[1]12月'!$A:$I,9,FALSE) -> 341126200502185637 | J35: =VLOOKUP(A35,'[1]12月'!$A:$J,10,FALSE) -> 15755297200 | K35: 0 | N35: =G35-K35 -> 0
A36: 蚌埠银泰店郑贤发 | B36: 蚌埠银泰店 | C36: 私教 | D36: 郑贤发 | E36: 在职 | F36: 7176.66 | G36: 65.3 | H36: 朝晖人力 | I36: =VLOOKUP(A36,[2]在职名单!$D:$AE,28,FALSE) -> 411524199010213613 | J36: =VLOOKUP(A36,[2]在职名单!$D:$AJ,33,FALSE) -> 15162958171 | K36: 65.3 | N36: =G36-K36 -> 0
A37: 蚌埠银泰店迟宁 | B37: 蚌埠银泰店 | C37: 私教 | D37: 迟宁 | E37: 在职 | F37: 290.76646 | G37: 0 | H37: 朝晖人力 | I37: 340311199711100644 | J37: 18855296695 | K37: 0 | N37: =G37-K37 -> 0
A38: 蚌埠银泰店李彬 | B38: 蚌埠银泰店 | C38: 泳教主管 | D38: 李彬 | E38: 在职 | F38: 4652.25 | G38: 0 | H38: =VLOOKUP(A38,'[1]12月'!$A:$H,8,FALSE) -> 朝晖人力 | I38: =VLOOKUP(A38,'[1]12月'!$A:$I,9,FALSE) -> 340321199910036238 | J38: =VLOOKUP(A38,'[1]12月'!$A:$J,10,FALSE) -> 15050227449 | K38: 0 | N38: =G38-K38 -> 0
A39: 蚌埠银泰店丁武帅 | B39: 蚌埠银泰店 | C39: 泳教 | D39: 丁武帅 | E39: 离职 | F39: 740.77 | G39: 0 | H39: 朝晖人力 | I39: =VLOOKUP(A39,[2]在职名单!$D:$AE,28,FALSE) -> 340321200211081852 | J39: =VLOOKUP(A39,[2]在职名单!$D:$AJ,33,FALSE) -> 18055277868 | K39: 0 | N39: =G39-K39 -> 0
A40: 蚌埠银泰店王宇恒 | B40: 蚌埠银泰店 | C40: 泳教 | D40: 王宇恒 | E40: 在职 | F40: 1652.6892 | G40: 0 | H40: 朝晖人力 | I40: 340321200206273438 | J40: 18155415334 | K40: 0 | N40: =G40-K40 -> 0
...

Sheet 2月
A1: 门店+姓名 | B1: 门店 | C1: 岗位 | D1: 姓名 | E1: 员工状态 | F1: 报税工资 | G1: 个税 | H1: 分公司 | I1: 身份证号 | J1: 联系方式 | K1: 实际个税 | L1: 备注 | N1: 差额 | P1: 差额1
D2: 刘甜甜 | F2: 17000 | G2: 360 | H2: 武汉山道 | I2: 420684198505276040 | K2: 360 | N2: =G2-K2 -> 0
D3: 杨艳 | F3: 2000 | G3: 0 | H3: 武汉山道 | I3: 420623198201201047 | K3: 0 | N3: =G3-K3 -> 0
D4: 刘建斌 | F4: 17000 | G4: 360 | H4: 武汉山道 | I4: 420684198402276056 | K4: 360 | N4: =G4-K4 -> 0
A5: 蚌埠吾悦店王格 | B5: 蚌埠吾悦店 | C5: 前台主管 | D5: 王格 | E5: 在职 | F5: 3945 | G5: 0 | H5: =VLOOKUP(A5,'1月'!A:H,8,FALSE) -> 朝晖人力 | I5: =VLOOKUP(A5,'1月'!A:I,9,FALSE) -> 340322200502054623 | J5: =VLOOKUP(A5,'1月'!A:J,10,FALSE) -> 15375468652 | K5: 0 | N5: =G5-K5 -> 0
A6: 蚌埠吾悦店李响 | B6: 蚌埠吾悦店 | C6: 前台 | D6: 李响 | E6: 在职 | F6: 2995 | G6: 0 | H6: =VLOOKUP(A6,'1月'!A:H,8,FALSE) -> 朝晖人力 | I6: =VLOOKUP(A6,'1月'!A:I,9,FALSE) -> 34030219860130002X | J6: =VLOOKUP(A6,'1月'!A:J,10,FALSE) -> 0 | K6: 0 | N6: =G6-K6 -> 0
A7: 蚌埠吾悦店赵红 | B7: 蚌埠吾悦店 | C7: 保洁 | D7: 赵红 | E7: 在职 | F7: 2390 | G7: 0 | H7: =VLOOKUP(A7,'1月'!A:H,8,FALSE) -> 朝晖人力 | I7: =VLOOKUP(A7,'1月'!A:I,9,FALSE) -> 340302197012310428 | J7: =VLOOKUP(A7,'1月'!A:J,10,FALSE) -> 16655298121 | K7: 0 | N7: =G7-K7 -> 0
A8: 蚌埠吾悦店陆春亮 | B8: 蚌埠吾悦店 | C8: 保洁 | D8: 陆春亮 | E8: 在职 | F8: 2390 | G8: 0 | H8: =VLOOKUP(A8,'1月'!A:H,8,FALSE) -> 朝晖人力 | I8: =VLOOKUP(A8,'1月'!A:I,9,FALSE) -> 340302196303260411 | J8: =VLOOKUP(A8,'1月'!A:J,10,FALSE) -> 13093664952 | K8: 0 | N8: =G8-K8 -> 0
A9: 蚌埠吾悦店万小建 | B9: 蚌埠吾悦店 | C9: 会籍经理 | D9: 万小建 | E9: 在职 | F9: 8853.207 | G9: 115.6 | H9: =VLOOKUP(A9,'1月'!A:H,8,FALSE) -> 朝晖人力 | I9: =VLOOKUP(A9,'1月'!A:I,9,FALSE) -> 340321198606010899 | J9: =VLOOKUP(A9,'1月'!A:J,10,FALSE) -> 1396528/6269 | K9: 115.6 | N9: =G9-K9 -> 0
A10: 蚌埠吾悦店邵家文 | B10: 蚌埠吾悦店 | C10: 会籍 | D10: 邵家文 | E10: 在职 | F10: 3425.48 | G10: 0 | H10: =VLOOKUP(A10,'1月'!A:H,8,FALSE) -> 朝晖人力 | I10: =VLOOKUP(A10,'1月'!A:I,9,FALSE) -> 340321200412065031 | J10: =VLOOKUP(A10,'1月'!A:J,10,FALSE) -> 17201600134 | K10: 0 | N10: =G10-K10 -> 0
A11: 蚌埠吾悦店赵惠春 | B11: 蚌埠吾悦店 | C11: 会籍 | D11: 赵惠春 | E11: 在职 | F11: 3415.68 | G11: 0 | H11: =VLOOKUP(A11,'1月'!A:H,8,FALSE) -> 朝晖人力 | I11: =VLOOKUP(A11,'1月'!A:I,9,FALSE) -> 370406200602046621 | J11: =VLOOKUP(A11,'1月'!A:J,10,FALSE) -> 19055243298 | K11: 0 | N11: =G11-K11 -> 0
A12: 蚌埠吾悦店刘庆康 | B12: 蚌埠吾悦店 | C12: 会籍 | D12: 刘庆康 | E12: 在职 | F12: 3279.8 | G12: 0 | H12: =VLOOKUP(A12,'1月'!A:H,8,FALSE) -> 朝晖人力 | I12: =VLOOKUP(A12,'1月'!A:I,9,FALSE) -> 340302200512121011 | J12: =VLOOKUP(A12,'1月'!A:J,10,FALSE) -> 0 | K12: 0 | N12: =G12-K12 -> 0
A13: 蚌埠吾悦店蒋维月 | B13: 蚌埠吾悦店 | C13: 私教 | D13: 蒋维月 | E13: 在职 | F13: 1700.874 | G13: 0 | H13: =VLOOKUP(A13,'1月'!A:H,8,FALSE) -> 朝晖人力 | I13: =VLOOKUP(A13,'1月'!A:I,9,FALSE) -> 340322200712043869 | J13: =VLOOKUP(A13,'1月'!A:J,10,FALSE) -> 18714837986 | K13: 0 | N13: =G13-K13 -> 0
A14: 蚌埠吾悦店栾金良 | B14: 蚌埠吾悦店 | C14: 私教经理 | D14: 栾金良 | E14: 在职 | F14: 9482.9096 | G14: 134.49 | H14: =VLOOKUP(A14,'1月'!A:H,8,FALSE) -> 朝晖人力 | I14: =VLOOKUP(A14,'1月'!A:I,9,FALSE) -> 321302198506180055 | J14: =VLOOKUP(A14,'1月'!A:J,10,FALSE) -> 13815786616 | K14: 134.49 | N14: =G14-K14 -> 0
A15: 蚌埠吾悦店曲蓝鹤 | B15: 蚌埠吾悦店 | C15: 私教 | D15: 曲蓝鹤 | E15: 在职 | F15: 4325.94 | G15: 0 | H15: =VLOOKUP(A15,'1月'!A:H,8,FALSE) -> 朝晖人力 | I15: =VLOOKUP(A15,'1月'!A:I,9,FALSE) -> 230505199011080214 | J15: =VLOOKUP(A15,'1月'!A:J,10,FALSE) -> 17755263617 | K15: 0 | N15: =G15-K15 -> 0
A16: 蚌埠吾悦店林康 | B16: 蚌埠吾悦店 | C16: 泳教主管 | D16: 林康 | E16: 在职 | F16: 4307.16 | G16: 0 | H16: =VLOOKUP(A16,'1月'!A:H,8,FALSE) -> 朝晖人力 | I16: =VLOOKUP(A16,'1月'!A:I,9,FALSE) -> 340321200212060850 | J16: =VLOOKUP(A16,'1月'!A:J,10,FALSE) -> 15056356955 | K16: 0 | N16: =G16-K16 -> 0
A17: 蚌埠吾悦店王新 | B17: 蚌埠吾悦店 | C17: 泳教 | D17: 王新 | E17: 在职 | F17: 708.83 | G17: 0 | H17: 朝晖人力 | I17: 340323199901154710 | J17: 15855762182 | K17: 0 | N17: =G17-K17 -> 0
A18: 蚌埠吾悦店郭锋 | B18: 蚌埠吾悦店 | C18: 泳教 | D18: 郭锋 | E18: 在职 | F18: 2074.6304 | G18: 0 | H18: 朝晖人力 | I18: 340323199306046037 | J18: 15855781030 | K18: 0 | N18: =G18-K18 -> 0
A19: 蚌埠银泰店彭莹莹 | B19: 蚌埠银泰店 | C19: 前台主管 | D19: 彭莹莹 | E19: 在职 | F19: 3500 | G19: 0 | H19: =VLOOKUP(A19,'1月'!A:H,8,FALSE) -> 朝晖人力 | I19: =VLOOKUP(A19,'1月'!A:I,9,FALSE) -> 34031119930320142X | J19: =VLOOKUP(A19,'1月'!A:J,10,FALSE) -> 18895657368 | K19: 0 | N19: =G19-K19 -> 0
A20: 蚌埠银泰店钱晴 | B20: 蚌埠银泰店 | C20: 前台 | D20: 钱晴 | E20: 离职 | F20: 340.74 | G20: 0 | H20: =VLOOKUP(A20,'1月'!A:H,8,FALSE) -> 朝晖人力 | I20: =VLOOKUP(A20,'1月'!A:I,9,FALSE) -> 340311200011021625 | J20: =VLOOKUP(A20,'1月'!A:J,10,FALSE) -> 0 | K20: 0 | N20: =G20-K20 -> 0
A21: 蚌埠银泰店王引 | B21: 蚌埠银泰店 | C21: 前台 | D21: 王引 | E21: 在职 | F21: 2645 | G21: 0 | H21: 朝晖人力 | I21: =VLOOKUP(A21,[2]在职名单!$D:$AE,28,FALSE) -> 340311199603300024 | J21: =VLOOKUP(A21,[2]在职名单!$D:$AJ,33,FALSE) -> 18297325069 | K21: 0 | N21: =G21-K21 -> 0
A22: 蚌埠银泰店李桂华 | B22: 蚌埠银泰店 | C22: 保洁 | D22: 李桂华 | E22: 在职 | F22: 2500 | G22: 0 | H22: =VLOOKUP(A22,'1月'!A:H,8,FALSE) -> 朝晖人力 | I22: =VLOOKUP(A22,'1月'!A:I,9,FALSE) -> 340123196511187707 | J22: =VLOOKUP(A22,'1月'!A:J,10,FALSE) -> 17705522172 | K22: 0 | N22: =G22-K22 -> 0
A23: 蚌埠银泰店沈智淮 | B23: 蚌埠银泰店 | C23: 保洁 | D23: 沈智怀 | E23: 在职 | F23: 2400 | G23: 0 | H23: 朝晖人力 | I23: 340302195510010496 沈智怀 | J23: =VLOOKUP(A23,'1月'!A:J,10,FALSE) -> 18109655880 | K23: 0 | N23: =G23-K23 -> 0
A24: 蚌埠银泰店蔡龙飞 | B24: 蚌埠银泰店 | C24: 会籍 | D24: 蔡龙飞 | E24: 在职 | F24: 3808.5 | G24: 0 | H24: =VLOOKUP(A24,'1月'!A:H,8,FALSE) -> 朝晖人力 | I24: =VLOOKUP(A24,'1月'!A:I,9,FALSE) -> 340321199303101253 | J24: =VLOOKUP(A24,'1月'!A:J,10,FALSE) -> 0 | K24: 0 | N24: =G24-K24 -> 0
A25: 蚌埠银泰店史玲娟 | B25: 蚌埠银泰店 | C25: 会籍 | D25: 史玲娟 | E25: 在职 | F25: 6824.408 | G25: 54.73 | H25: =VLOOKUP(A25,'1月'!A:H,8,FALSE) -> 朝晖人力 | I25: =VLOOKUP(A25,'1月'!A:I,9,FALSE) -> 340323200311216227 | J25: =VLOOKUP(A25,'1月'!A:J,10,FALSE) -> 15755212422 | K25: 54.73 | N25: =G25-K25 -> 0
A26: 蚌埠银泰店张鑫杰 | B26: 蚌埠银泰店 | C26: 会籍 | D26: 张鑫杰 | E26: 在职 | F26: 3957.35 | G26: 0 | H26: =VLOOKUP(A26,'1月'!A:H,8,FALSE) -> 朝晖人力 | I26: =VLOOKUP(A26,'1月'!A:I,9,FALSE) -> 410221200502176512 | J26: =VLOOKUP(A26,'1月'!A:J,10,FALSE) -> 18836866156 | K26: 0 | N26: =G26-K26 -> 0
A27: 蚌埠银泰店孙齐云 | B27: 蚌埠银泰店 | C27: 私教经理 | D27: 孙齐云 | E27: 在职 | F27: 5991.0862 | G27: 29.73 | H27: =VLOOKUP(A27,'1月'!A:H,8,FALSE) -> 朝晖人力 | I27: =VLOOKUP(A27,'1月'!A:I,9,FALSE) -> 342626199407204919 | J27: =VLOOKUP(A27,'1月'!A:J,10,FALSE) -> 13851536096 | K27: 29.73 | N27: =G27-K27 -> 0
A28: 蚌埠银泰店郑贤发 | B28: 蚌埠银泰店 | C28: 私教 | D28: 郑贤发 | E28: 在职 | F28: 7756.9266 | G28: 82.71 | H28: =VLOOKUP(A28,'1月'!A:H,8,FALSE) -> 朝晖人力 | I28: =VLOOKUP(A28,'1月'!A:I,9,FALSE) -> 411524199010213613 | J28: =VLOOKUP(A28,'1月'!A:J,10,FALSE) -> 15162958171 | K28: 82.71 | N28: =G28-K28 -> 0
A29: 蚌埠银泰店迟宁 | B29: 蚌埠银泰店 | C29: 私教 | D29: 迟宁 | E29: 在职 | F29: 1273.05 | G29: 0 | H29: =VLOOKUP(A29,'1月'!A:H,8,FALSE) -> 朝晖人力 | I29: =VLOOKUP(A29,'1月'!A:I,9,FALSE) -> 340311199711100644 | J29: =VLOOKUP(A29,'1月'!A:J,10,FALSE) -> 18855296695 | K29: 0 | N29: =G29-K29 -> 0
A30: 蚌埠银泰店李彬 | B30: 蚌埠银泰店 | C30: 泳教主管 | D30: 李彬 | E30: 在职 | F30: 3716.9 | G30: 0 | H30: =VLOOKUP(A30,'1月'!A:H,8,FALSE) -> 朝晖人力 | I30: =VLOOKUP(A30,'1月'!A:I,9,FALSE) -> 340321199910036238 | J30: =VLOOKUP(A30,'1月'!A:J,10,FALSE) -> 15050227449 | K30: 0 | N30: =G30-K30 -> 0
A31: 蚌埠银泰店王宇恒 | B31: 蚌埠银泰店 | C31: 泳教 | D31: 王宇恒 | E31: 在职 | F31: 3981.24 | G31: 0 | H31: =VLOOKUP(A31,'1月'!A:H,8,FALSE) -> 朝晖人力 | I31: =VLOOKUP(A31,'1月'!A:I,9,FALSE) -> 340321200206273438 | J31: =VLOOKUP(A31,'1月'!A:J,10,FALSE) -> 18155415334 | K31: 0 | N31: =G31-K31 -> 0
A32: 蚌埠银泰店高传宏 | B32: 蚌埠银泰店 | C32: 安全员 | D32: 高传宏 | E32: 在职 | F32: 2500 | G32: 0 | H32: =VLOOKUP(A32,'1月'!A:H,8,FALSE) -> 朝晖人力 | I32: =VLOOKUP(A32,'1月'!A:I,9,FALSE) -> 340304196904170633 | J32: =VLOOKUP(A32,'1月'!A:J,10,FALSE) -> 13295524310 | K32: 0 | N32: =G32-K32 -> 0
A33: 淮北吾悦店欧林雨 | B33: 淮北吾悦店 | C33: 前台主管 | D33: 欧林雨 | E33: 在职 | F33: 4565.4 | G33: 0 | H33: =VLOOKUP(A33,'1月'!A:H,8,FALSE) -> 朝晖人力 | I33: =VLOOKUP(A33,'1月'!A:I,9,FALSE) -> 342222200201195824 | J33: =VLOOKUP(A33,'1月'!A:J,10,FALSE) -> 19856101932 | K33: 0 | N33: =G33-K33 -> 0
A34: 淮北吾悦店王紫妍 | B34: 淮北吾悦店 | C34: 前台 | D34: 王紫妍 | E34: 在职 | F34: 3297.5 | G34: 0 | H34: =VLOOKUP(A34,'1月'!A:H,8,FALSE) -> 朝晖人力 | I34: =VLOOKUP(A34,'1月'!A:I,9,FALSE) -> 340602200312120424 | J34: =VLOOKUP(A34,'1月'!A:J,10,FALSE) -> 17756143344 | K34: 0 | N34: =G34-K34 -> 0
A35: 淮北吾悦店高泉 | B35: 淮北吾悦店 | C35: 保洁 | D35: 高泉 | E35: 在职 | F35: 2390 | G35: 0 | H35: =VLOOKUP(A35,'1月'!A:H,8,FALSE) -> 朝晖人力 | I35: =VLOOKUP(A35,'1月'!A:I,9,FALSE) -> 342123196308128893 | J35: =VLOOKUP(A35,'1月'!A:J,10,FALSE) -> 15156191196 | K35: 0 | N35: =G35-K35 -> 0
... A52: 宿州吾悦店涂佩 | B52: 宿州吾悦店 | C52: 前台主管 | D52: 涂佩 | E52: 在职 | F52: 3675 | G52: 0 | H52: =VLOOKUP(A52,'1月'!A:H,8,FALSE) -> 朝晖人力 | I52: =VLOOKUP(A52,'1月'!A:I,9,FALSE) -> 421122199006094225 | J52: =VLOOKUP(A52,'1月'!A:J,10,FALSE) -> 15655706018 | K52: 0 | N52: =G52-K52 -> 0
A53: 宿州吾悦店陈晨 | B53: 宿州吾悦店 | C53: 前台 | D53: 陈晨 | E53: 在职 | F53: 2445 | G53: 0 | H53: =VLOOKUP(A53,'1月'!A:H,8,FALSE) -> 朝晖人力 | I53: 341323200406160562 | J53: =VLOOKUP(A53,'1月'!A:J,10,FALSE) -> 15398200885 | K53: 0 | N53: =G53-K53 -> 0
A54: 宿州吾悦店王淑萍 | B54: 宿州吾悦店 | C54: 保洁 | D54: 王淑萍 | E54: 在职 | F54: 2385 | G54: 0 | H54: =VLOOKUP(A54,'1月'!A:H,8,FALSE) -> 朝晖人力 | I54: =VLOOKUP(A54,'1月'!A:I,9,FALSE) -> 340604196008270480 | J54: =VLOOKUP(A54,'1月'!A:J,10,FALSE) -> 13026041688 | K54: 0 | N54: =G54-K54 -> 0
A55: 宿州吾悦店哈大宝 | B55: 宿州吾悦店 | C55: 保洁 | D55: 哈大宝 | E55: 在职 | F55: 2385 | G55: 0 | H55: =VLOOKUP(A55,'1月'!A:H,8,FALSE) -> 朝晖人力 | I55: =VLOOKUP(A55,'1月'!A:I,9,FALSE) -> 340621196008214813 | J55: =VLOOKUP(A55,'1月'!A:J,10,FALSE) -> 13866590052 | K55: 0 | N55: =G55-K55 -> 0
A56: 宿州吾悦店李金鞠 | B56: 宿州吾悦店 | C56: 会籍经理 | D56: 李金鞠 | E56: 在职 | F56: 8228.764 | G56: 0 | H56: =VLOOKUP(A56,'1月'!A:H,8,FALSE) -> 朝晖人力 | I56: =VLOOKUP(A56,'1月'!A:I,9,FALSE) -> 342201198804070420 | J56: =VLOOKUP(A56,'1月'!A:J,10,FALSE) -> 18705579951 | K56: 0 | N56: =G56-K56 -> 0
...

Sheet 3月
A1: 门店+姓名 | B1: 门店 | C1: 岗位 | D1: 姓名 | E1: 员工状态 | F1: 报税工资 | G1: 个税 | H1: 分公司 | I1: 身份证号 | J1: 联系方式 | K1: 实际个税 | L1: 备注 | N1: 差额 | P1: 差额1
D2: 刘甜甜 | F2: 17000 | G2: 360 | H2: 武汉山道 | I2: 420684198505276040 | K2: 360 | N2: =G2-K2 -> 0
D3: 杨艳 | F3: 2000 | G3: 0 | H3: 武汉山道 | I3: 420623198201201047 | K3: 0 | N3: =G3-K3 -> 0
D4: 刘建斌 | F4: 17000 | G4: 360 | H4: 武汉山道 | I4: 420684198402276056 | K4: 360 | N4: =G4-K4 -> 0
A5: 蚌埠吾悦店王格 | B5: 蚌埠吾悦店 | C5: 前台主管 | D5: 王格 | E5: 在职 | F5: 3226.73 | G5: 0 | H5: =VLOOKUP(A5,'2月'!A:H,8,FALSE) -> 朝晖人力 | I5: =VLOOKUP(A5,'2月'!A:I,9,FALSE) -> 340322200502054623 | J5: =VLOOKUP(A5,'2月'!A:J,10,FALSE) -> 15375468652 | K5: 0 | N5: =G5-K5 -> 0
A6: 蚌埠吾悦店李响 | B6: 蚌埠吾悦店 | C6: 前台 | D6: 李响 | E6: 在职 | F6: 2185 | G6: 0 | H6: =VLOOKUP(A6,'2月'!A:H,8,FALSE) -> 朝晖人力 | I6: =VLOOKUP(A6,'2月'!A:I,9,FALSE) -> 34030219860130002X | J6: =VLOOKUP(A6,'2月'!A:J,10,FALSE) -> 0 | K6: 0 | N6: =G6-K6 -> 0
A7: 蚌埠吾悦店赵红 | B7: 蚌埠吾悦店 | C7: 保洁 | D7: 赵红 | E7: 在职 | F7: 1200 | G7: 0 | H7: =VLOOKUP(A7,'2月'!A:H,8,FALSE) -> 朝晖人力 | I7: =VLOOKUP(A7,'2月'!A:I,9,FALSE) -> 340302197012310428 | J7: =VLOOKUP(A7,'2月'!A:J,10,FALSE) -> 16655298121 | K7: 0 | N7: =G7-K7 -> 0
A8: 蚌埠吾悦店陆春亮 | B8: 蚌埠吾悦店 | C8: 保洁 | D8: 陆春亮 | E8: 在职 | F8: 1200 | G8: 0 | H8: =VLOOKUP(A8,'2月'!A:H,8,FALSE) -> 朝晖人力 | I8: =VLOOKUP(A8,'2月'!A:I,9,FALSE) -> 340302196303260411 | J8: =VLOOKUP(A8,'2月'!A:J,10,FALSE) -> 13093664952 | K8: 0 | N8: =G8-K8 -> 0
A9: 蚌埠吾悦店万小建 | B9: 蚌埠吾悦店 | C9: 会籍经理 | D9: 万小建 | E9: 在职 | F9: 7353.46 | G9: 70.6 | H9: =VLOOKUP(A9,'2月'!A:H,8,FALSE) -> 朝晖人力 | I9: =VLOOKUP(A9,'2月'!A:I,9,FALSE) -> 340321198606010899 | J9: =VLOOKUP(A9,'2月'!A:J,10,FALSE) -> 1396528/6269 | K9: 70.6 | N9: =G9-K9 -> 0
A10: 蚌埠吾悦店邵家文 | B10: 蚌埠吾悦店 | C10: 会籍 | D10: 邵家文 | E10: 在职 | F10: 3719.21 | G10: 0 | H10: =VLOOKUP(A10,'2月'!A:H,8,FALSE) -> 朝晖人力 | I10: =VLOOKUP(A10,'2月'!A:I,9,FALSE) -> 340321200412065031 | J10: =VLOOKUP(A10,'2月'!A:J,10,FALSE) -> 17201600134 | K10: 0 | N10: =G10-K10 -> 0
A11: 蚌埠吾悦店赵惠春 | B11: 蚌埠吾悦店 | C11: 会籍 | D11: 赵惠春 | E11: 在职 | F11: 4751.07 | G11: 0 | H11: =VLOOKUP(A11,'2月'!A:H,8,FALSE) -> 朝晖人力 | I11: =VLOOKUP(A11,'2月'!A:I,9,FALSE) -> 370406200602046621 | J11: =VLOOKUP(A11,'2月'!A:J,10,FALSE) -> 19055243298 | K11: 0 | N11: =G11-K11 -> 0
A12: 蚌埠吾悦店刘庆康 | B12: 蚌埠吾悦店 | C12: 会籍 | D12: 刘庆康 | E12: 在职 | F12: 1537.08 | G12: 0 | H12: =VLOOKUP(A12,'2月'!A:H,8,FALSE) -> 朝晖人力 | I12: =VLOOKUP(A12,'2月'!A:I,9,FALSE) -> 340302200512121011 | J12: =VLOOKUP(A12,'2月'!A:J,10,FALSE) -> 0 | K12: 0 | N12: =G12-K12 -> 0
A13: 蚌埠吾悦店蒋维月 | B13: 蚌埠吾悦店 | C13: 私教 | D13: 蒋维月 | E13: 在职 | F13: 1124.658 | G13: 0 | H13: =VLOOKUP(A13,'2月'!A:H,8,FALSE) -> 朝晖人力 | I13: =VLOOKUP(A13,'2月'!A:I,9,FALSE) -> 340322200712043869 | J13: =VLOOKUP(A13,'2月'!A:J,10,FALSE) -> 18714837986 | K13: 0 | N13: =G13-K13 -> 0
A14: 蚌埠吾悦店栾金良 | B14: 蚌埠吾悦店 | C14: 私教经理 | D14: 栾金良 | E14: 在职 | F14: 9493.3833 | G14: 134.8 | H14: =VLOOKUP(A14,'2月'!A:H,8,FALSE) -> 朝晖人力 | I14: =VLOOKUP(A14,'2月'!A:I,9,FALSE) -> 321302198506180055 | J14: =VLOOKUP(A14,'2月'!A:J,10,FALSE) -> 13815786616 | K14: 134.8 | N14: =G14-K14 -> 0
A15: 蚌埠吾悦店曲蓝鹤 | B15: 蚌埠吾悦店 | C15: 私教 | D15: 曲蓝鹤 | E15: 在职 | F15: 3416.8725 | G15: 0 | H15: =VLOOKUP(A15,'2月'!A:H,8,FALSE) -> 朝晖人力 | I15: =VLOOKUP(A15,'2月'!A:I,9,FALSE) -> 230505199011080214 | J15: =VLOOKUP(A15,'2月'!A:J,10,FALSE) -> 17755263617 | K15: 0 | N15: =G15-K15 -> 0
A16: 蚌埠吾悦店林康 | B16: 蚌埠吾悦店 | C16: 泳教主管 | D16: 林康 | E16: 在职 | F16: 5061.17 | G16: 0 | H16: =VLOOKUP(A16,'2月'!A:H,8,FALSE) -> 朝晖人力 | I16: =VLOOKUP(A16,'2月'!A:I,9,FALSE) -> 340321200212060850 | J16: =VLOOKUP(A16,'2月'!A:J,10,FALSE) -> 15056356955 | K16: 0 | N16: =G16-K16 -> 0
A17: 蚌埠银泰店张健 | B17: 蚌埠银泰店 | C17: 店长 | D17: 张健 | E17: 在职 | F17: 5792.3558 | G17: 23.77 | H17: 朝晖人力 | I17: =VLOOKUP(A17,[3]在职名单!$D:$AE,28,FALSE) -> 342601199308085099 | J17: =VLOOKUP(A17,[3]在职名单!$D:$AJ,33,FALSE) -> 18556503671 | K17: 23.77 | N17: =G17-K17 -> 0
A18: 蚌埠银泰店彭莹莹 | B18: 蚌埠银泰店 | C18: 前台主管 | D18: 彭莹莹 | E18: 在职 | F18: 2826.92 | G18: 0 | H18: =VLOOKUP(A18,'2月'!A:H,8,FALSE) -> 朝晖人力 | I18: =VLOOKUP(A18,'2月'!A:I,9,FALSE) -> 34031119930320142X | J18: =VLOOKUP(A18,'2月'!A:J,10,FALSE) -> 18895657368 | K18: 0 | N18: =G18-K18 -> 0
A19: 蚌埠银泰店王引 | B19: 蚌埠银泰店 | C19: 前台 | D19: 王引 | E19: 在职 | F19: 2284.62 | G19: 0 | H19: =VLOOKUP(A19,'2月'!A:H,8,FALSE) -> 朝晖人力 | I19: =VLOOKUP(A19,'2月'!A:I,9,FALSE) -> 340311199603300024 | J19: =VLOOKUP(A19,'2月'!A:J,10,FALSE) -> 18297325069 | K19: 0 | N19: =G19-K19 -> 0
A20: 蚌埠银泰店李桂华 | B20: 蚌埠银泰店 | C20: 保洁 | D20: 李桂华 | E20: 在职 | F20: 1538.46 | G20: 0 | H20: =VLOOKUP(A20,'2月'!A:H,8,FALSE) -> 朝晖人力 | I20: =VLOOKUP(A20,'2月'!A:I,9,FALSE) -> 340123196511187707 | J20: =VLOOKUP(A20,'2月'!A:J,10,FALSE) -> 17705522172 | K20: 0 | N20: =G20-K20 -> 0
A21: 蚌埠银泰店沈智淮 | B21: 蚌埠银泰店 | C21: 保洁 | D21: 沈智淮 | E21: 离职 | F21: 1384.62 | G21: 0 | H21: =VLOOKUP(A21,'2月'!A:H,8,FALSE) -> 朝晖人力 | I21: =VLOOKUP(A21,'2月'!A:I,9,FALSE) -> 340302195510010496 沈智怀 | J21: =VLOOKUP(A21,'2月'!A:J,10,FALSE) -> 18109655880 | K21: 0 | N21: =G21-K21 -> 0
A22: 蚌埠银泰店王良顺 | B22: 蚌埠银泰店 | C22: 保洁 | D22: 王良顺 | E22: 在职 | F22: 92.312308 | G22: 0 | H22: 朝晖人力 | I22: =VLOOKUP(A22,[3]在职名单!$D:$AE,28,FALSE) -> 340301196210230030 | J22: =VLOOKUP(A22,[3]在职名单!$D:$AJ,33,FALSE) -> 13965298264 | K22: 0 | N22: =G22-K22 -> 0
A23: 蚌埠银泰店史玲娟 | B23: 蚌埠银泰店 | C23: 会籍 | D23: 史玲娟 | E23: 在职 | F23: 9029.4405 | G23: 120.89 | H23: =VLOOKUP(A23,'2月'!A:H,8,FALSE) -> 朝晖人力 | I23: =VLOOKUP(A23,'2月'!A:I,9,FALSE) -> 340323200311216227 | J23: =VLOOKUP(A23,'2月'!A:J,10,FALSE) -> 15755212422 | K23: 120.89 | N23: =G23-K23 -> 0
A24: 蚌埠银泰店荣闯 | B24: 蚌埠银泰店 | C24: 会籍 | D24: 荣闯 | E24: 在职 | F24: 1502.72 | G24: 0 | H24: 朝晖人力 | I24: 340321200411126533 | J24: 13695526081 | K24: 0 | N24: =G24-K24 -> 0
A25: 蚌埠银泰店邵怡 | B25: 蚌埠银泰店 | C25: 会籍 | D25: 邵怡 | E25: 在职 | F25: 1111.49 | G25: 0 | H25: 朝晖人力 | I25: =VLOOKUP(A25,[3]在职名单!$D:$AE,28,FALSE) -> 340321200508126572 | J25: =VLOOKUP(A25,[3]在职名单!$D:$AJ,33,FALSE) -> 19215600959 | K25: 0 | N25: =G25-K25 -> 0
A26: 蚌埠银泰店孙齐云 | B26: 蚌埠银泰店 | C26: 私教经理 | D26: 孙齐云 | E26: 在职 | F26: 7331.3253 | G26: 69.94 | H26: =VLOOKUP(A26,'2月'!A:H,8,FALSE) -> 朝晖人力 | I26: =VLOOKUP(A26,'2月'!A:I,9,FALSE) -> 342626199407204919 | J26: =VLOOKUP(A26,'2月'!A:J,10,FALSE) -> 13851536096 | K26: 69.94 | N26: =G26-K26 -> 0
A27: 蚌埠银泰店郑贤发 | B27: 蚌埠银泰店 | C27: 私教 | D27: 郑贤发 | E27: 在职 | F27: 5893.2023 | G27: 26.79 | H27: =VLOOKUP(A27,'2月'!A:H,8,FALSE) -> 朝晖人力 | I27: =VLOOKUP(A27,'2月'!A:I,9,FALSE) -> 411524199010213613 | J27: =VLOOKUP(A27,'2月'!A:J,10,FALSE) -> 15162958171 | K27: 26.79 | N27: =G27-K27 -> 0
A28: 蚌埠银泰店李可 | B28: 蚌埠银泰店 | C28: 私教 | D28: 李可 | E28: 在职 | F28: 1427.865 | G28: 0 | H28: 朝晖人力 | I28: =VLOOKUP(A28,[3]在职名单!$D:$AE,28,FALSE) -> 340404200104240028 | J28: =VLOOKUP(A28,[3]在职名单!$D:$AJ,33,FALSE) -> 18055464203 | K28: 0 | N28: =G28-K28 -> 0
A29: 蚌埠银泰店李彬 | B29: 蚌埠银泰店 | C29: 泳教主管 | D29: 李彬 | E29: 在职 | F29: 2542.33 | G29: 0 | H29: =VLOOKUP(A29,'2月'!A:H,8,FALSE) -> 朝晖人力 | I29: =VLOOKUP(A29,'2月'!A:I,9,FALSE) -> 340321199910036238 | J29: =VLOOKUP(A29,'2月'!A:J,10,FALSE) -> 15050227449 | K29: 0 | N29: =G29-K29 -> 0
A30: 蚌埠银泰店王宇恒 | B30: 蚌埠银泰店 | C30: 泳教 | D30: 王宇恒 | E30: 在职 | F30: 6177.695 | G30: 4.77 | H30: =VLOOKUP(A30,'2月'!A:H,8,FALSE) -> 朝晖人力 | I30: =VLOOKUP(A30,'2月'!A:I,9,FALSE) -> 340321200206273438 | J30: =VLOOKUP(A30,'2月'!A:J,10,FALSE) -> 18155415334 | K30: 4.77 | N30: =G30-K30 -> 0
A31: 蚌埠银泰店高传宏 | B31: 蚌埠银泰店 | C31: 安全员 | D31: 高传宏 | E31: 在职 | F31: 1415.38 | G31: 0 | H31: =VLOOKUP(A31,'2月'!A:H,8,FALSE) -> 朝晖人力 | I31: =VLOOKUP(A31,'2月'!A:I,9,FALSE) -> 340304196904170633 | J31: =VLOOKUP(A31,'2月'!A:J,10,FALSE) -> 13295524310 | K31: 0 | N31: =G31-K31 -> 0
A32: 淮北吾悦店欧林雨 | B32: 淮北吾悦店 | C32: 前台主管 | D32: 欧林雨 | E32: 在职 | F32: 3656.3872 | G32: 0 | H32: =VLOOKUP(A32,'2月'!A:H,8,FALSE) -> 朝晖人力 | I32: =VLOOKUP(A32,'2月'!A:I,9,FALSE) -> 342222200201195824 | J32: =VLOOKUP(A32,'2月'!A:J,10,FALSE) -> 19856101932 | K32: 0 | N32: =G32-K32 -> 0
A33: 淮北吾悦店王紫妍 | B33: 淮北吾悦店 | C33: 前台 | D33: 王紫妍 | E33: 在职 | F33: 2353.6847 | G33: 0 | H33: =VLOOKUP(A33,'2月'!A:H,8,FALSE) -> 朝晖人力 | I33: =VLOOKUP(A33,'2月'!A:I,9,FALSE) -> 340602200312120424 | J33: =VLOOKUP(A33,'2月'!A:J,10,FALSE) -> 17756143344 | K33: 0 | N33: =G33-K33 -> 0
A34: 淮北吾悦店高泉 | B34: 淮北吾悦店 | C34: 保洁 | D34: 高泉 | E34: 在职 | F34: 1375 | G34: 0 | H34: =VLOOKUP(A34,'2月'!A:H,8,FALSE) -> 朝晖人力 | I34: =VLOOKUP(A34,'2月'!A:I,9,FALSE) -> 342123196308128893 | J34: =VLOOKUP(A34,'2月'!A:J,10,FALSE) -> 15156191196 | K34: 0 | N34: =G34-K34 -> 0
A35: 淮南吾悦店周涛 | B35: 淮南吾悦店 | C35: 店长 | D35: 周涛 | E35: 在职 | F35: 19243.915 | G35: 427.32 | H35: =VLOOKUP(A35,'2月'!A:H,8,FALSE) -> 武汉山道 | I35: =VLOOKUP(A35,'2月'!A:I,9,FALSE) -> 421125198511060012 | J35: =VLOOKUP(A35,'2月'!A:J,10,FALSE) -> 15927100269 | K35: 427.32 | N35: =G35-K35 -> 0
A36: 淮南吾悦店刘徐晴 | B36: 淮南吾悦店 | C36: 前台主管 | D36: 刘徐晴 | E36: 在职 | F36: 2615.39 | G36: 0 | H36: =VLOOKUP(A36,'2月'!A:H,8,FALSE) -> 朝晖人力 | I36: =VLOOKUP(A36,'2月'!A:I,9,FALSE) -> 340406199205233043 | J36: =VLOOKUP(A36,'2月'!A:J,10,FALSE) -> 17730160242 | K36: 0 | N36: =G36-K36 -> 0
A37: 淮南吾悦店张晓冬 | B37: 淮南吾悦店 | C37: 前台 | D37: 张晓冬 | E37: 在职 | F37: 2070 | G37: 0 | H37: =VLOOKUP(A37,'2月'!A:H,8,FALSE) -> 朝晖人力 | I37: =VLOOKUP(A37,'2月'!A:I,9,FALSE) -> 42282519991003064X | J37: =VLOOKUP(A37,'2月'!A:J,10,FALSE) -> 15623356005 | K37: 0 | N37: =G37-K37 -> 0
A38: 淮南吾悦店林丽 | B38: 淮南吾悦店 | C38: 保洁 | D38: 林丽 | E38: 在职 | F38: 1151.61 | G38: 0 | H38: =VLOOKUP(A38,'2月'!A:H,8,FALSE) -> 朝晖人力 | I38: =VLOOKUP(A38,'2月'!A:I,9,FALSE) -> 340406197002032242 | J38: =VLOOKUP(A38,'2月'!A:J,10,FALSE) -> 19855485653 | K38: 0 | N38: =G38-K38 -> 0
A39: 淮南吾悦店许邦元 | B39: 淮南吾悦店 | C39: 保洁 | D39: 许邦元 | E39: 在职 | F39: 1228.39 | G39: 0 | H39: =VLOOKUP(A39,'2月'!A:H,8,FALSE) -> 朝晖人力 | I39: =VLOOKUP(A39,'2月'!A:I,9,FALSE) -> 340402196002250012 | J39: =VLOOKUP(A39,'2月'!A:J,10,FALSE) -> 15755400059 | K39: 0 | N39: =G39-K39 -> 0
A40: 淮南吾悦店焦家喻 | B40: 淮南吾悦店 | C40: 会籍经理 | D40: 焦家喻 | E40: 在职 | F40: 7173.34 | G40: 65.2 | H40: =VLOOKUP(A40,'2月'!A:H,8,FALSE) -> 朝晖人力 | I40: =VLOOKUP(A40,'2月'!A:I,9,FALSE) -> 422326198512295217 | J40: =VLOOKUP(A40,'2月'!A:J,10,FALSE) -> 13997538150 | K40: 65.2 | N40: =G40-K40 -> 0
...

Sheet 4月
A1: 门店+姓名 | B1: 门店 | C1: 岗位 | D1: 姓名 | E1: 员工状态 | F1: 报税工资 | G1: 个税 | H1: 基本养老保险费 | I1: 基本医疗保险费 | J1: 失业保险费 | K1: 分公司 | L1: 身份证号 | M1: 联系方式 | N1: 实际个税 | O1: 备注 | Q1: 差额 | S1: 差额1
D2: 刘甜甜 | F2: 17000 | H2: 1360 | I2: 347 | J2: 51 | K2: 武汉山道 | L2: 420684198505276040 | N2: 307.26 | Q2: 0
D3: 杨艳 | F3: 2000 | H3: 359.84 | I3: 96.96 | J3: 13.49 | K3: 武汉山道 | L3: 420623198201201047 | N3: 0 | Q3: =G3-N3 -> 0
D4: 刘建斌 | F4: 17000 | H4: 1360 | I4: 347 | J4: 51 | K4: 武汉山道 | L4: 420684198402276056 | M4: 15927000009 | N4: 307.26 | Q4: 0
A5: 蚌埠吾悦店王格 | B5: 蚌埠吾悦店 | C5: 前台主管 | D5: 王格 | E5: 在职 | F5: 2220 | G5: 0 | K5: =VLOOKUP(A5,'3月'!A:H,8,FALSE) -> 朝晖人力 | L5: =VLOOKUP(A5,'3月'!A:I,9,FALSE) -> 340322200502054623 | M5: =VLOOKUP(A5,'3月'!A:J,10,FALSE) -> 15375468652 | N5: 0 | Q5: =G5-N5 -> 0
A6: 蚌埠吾悦店李响 | B6: 蚌埠吾悦店 | C6: 前台 | D6: 李响 | E6: 在职 | F6: 1671 | G6: 0 | K6: =VLOOKUP(A6,'3月'!A:H,8,FALSE) -> 朝晖人力 | L6: =VLOOKUP(A6,'3月'!A:I,9,FALSE) -> 34030219860130002X | M6: =VLOOKUP(A6,'3月'!A:J,10,FALSE) -> 0 | N6: 0 | Q6: =G6-N6 -> 0
A7: 蚌埠吾悦店孙颖 | B7: 蚌埠吾悦店 | C7: 前台 | D7: 孙颖 | E7: 在职 | F7: 208.34 | G7: 0 | K7: 朝晖人力 | L7: =VLOOKUP(A7,[4]在职名单!$D:$AE,28,FALSE) -> 340321200212088263 | M7: =VLOOKUP(A7,[4]在职名单!$D:$AJ,33,FALSE) -> 13155218936 | N7: 0 | Q7: =G7-N7 -> 0
A8: 蚌埠吾悦店赵红 | B8: 蚌埠吾悦店 | C8: 保洁 | D8: 赵红 | E8: 在职 | F8: 1380 | G8: 0 | K8: 朝晖人力 | L8: =VLOOKUP(A8,'3月'!A:I,9,FALSE) -> 340302197012310428 | M8: =VLOOKUP(A8,'3月'!A:J,10,FALSE) -> 16655298121 | N8: 0 | Q8: =G8-N8 -> 0
A9: 蚌埠吾悦店陆春亮 | B9: 蚌埠吾悦店 | C9: 保洁 | D9: 陆春亮 | E9: 在职 | F9: 1380 | G9: 0 | K9: 朝晖人力 | L9: =VLOOKUP(A9,'3月'!A:I,9,FALSE) -> 340302196303260411 | M9: =VLOOKUP(A9,'3月'!A:J,10,FALSE) -> 13093664952 | N9: 0 | Q9: =G9-N9 -> 0
A10: 蚌埠吾悦店万小建 | B10: 蚌埠吾悦店 | C10: 会籍经理 | D10: 万小建 | E10: 在职 | F10: 863.412 | G10: 0 | K10: 朝晖人力 | L10: =VLOOKUP(A10,'3月'!A:I,9,FALSE) -> 340321198606010899 | M10: =VLOOKUP(A10,'3月'!A:J,10,FALSE) -> 1396528/6269 | N10: 0 | Q10: =G10-N10 -> 0
A11: 蚌埠吾悦店邵家文 | B11: 蚌埠吾悦店 | C11: 会籍 | D11: 邵家文 | E11: 在职 | F11: 816 | G11: 0 | K11: 朝晖人力 | L11: =VLOOKUP(A11,'3月'!A:I,9,FALSE) -> 340321200412065031 | M11: =VLOOKUP(A11,'3月'!A:J,10,FALSE) -> 17201600134 | N11: 0 | Q11: =G11-N11 -> 0
A12: 蚌埠吾悦店赵惠春 | B12: 蚌埠吾悦店 | C12: 会籍 | D12: 赵惠春 | E12: 在职 | F12: 880 | G12: 0 | K12: 朝晖人力 | L12: =VLOOKUP(A12,'3月'!A:I,9,FALSE) -> 370406200602046621 | M12: =VLOOKUP(A12,'3月'!A:J,10,FALSE) -> 19055243298 | N12: 0 | Q12: =G12-N12 -> 0
A13: 蚌埠吾悦店刘庆康 | B13: 蚌埠吾悦店 | C13: 会籍 | D13: 刘庆康 | E13: 在职 | F13: 320 | G13: 0 | K13: 朝晖人力 | L13: =VLOOKUP(A13,'3月'!A:I,9,FALSE) -> 340302200512121011 | M13: =VLOOKUP(A13,'3月'!A:J,10,FALSE) -> 0 | N13: 0 | Q13: =G13-N13 -> 0
A14: 蚌埠吾悦店荣闯 | B14: 蚌埠吾悦店 | C14: 会籍 | D14: 荣闯 | E14: 在职 | F14: 416.67 | G14: 0 | K14: 朝晖人力 | L14: =VLOOKUP(A14,[4]在职名单!$D:$AE,28,FALSE) -> 340321200411126533 | M14: =VLOOKUP(A14,[4]在职名单!$D:$AJ,33,FALSE) -> 13695526081 | N14: 0 | Q14: =G14-N14 -> 0
A15: 蚌埠吾悦店朱文娟 | B15: 蚌埠吾悦店 | C15: 会籍 | D15: 朱文娟 | E15: 在职 | F15: 91.66 | G15: 0 | K15: 朝晖人力 | L15: =VLOOKUP(A15,[4]在职名单!$D:$AE,28,FALSE) -> 340321199612088646 | M15: 13155218935 | N15: 0 | Q15: =G15-N15 -> 0
A16: 蚌埠吾悦店栾金良 | B16: 蚌埠吾悦店 | C16: 私教经理 | D16: 栾金良 | E16: 在职 | F16: 1910.868 | G16: 0 | K16: 朝晖人力 | L16: =VLOOKUP(A16,'3月'!A:I,9,FALSE) -> 321302198506180055 | M16: =VLOOKUP(A16,'3月'!A:J,10,FALSE) -> 13815786616 | N16: 0 | Q16: =G16-N16 -> 0
A17: 蚌埠吾悦店曲蓝鹤 | B17: 蚌埠吾悦店 | C17: 私教 | D17: 曲蓝鹤 | E17: 在职 | F17: 405 | G17: 0 | K17: 朝晖人力 | L17: =VLOOKUP(A17,'3月'!A:I,9,FALSE) -> 230505199011080214 | M17: =VLOOKUP(A17,'3月'!A:J,10,FALSE) -> 17755263617 | N17: 0 | Q17: =G17-N17 -> 0
A18: 蚌埠吾悦店林康 | B18: 蚌埠吾悦店 | C18: 泳教主管 | D18: 林康 | E18: 在职 | F18: 320 | G18: 0 | K18: 朝晖人力 | L18: =VLOOKUP(A18,'3月'!A:I,9,FALSE) -> 340321200212060850 | M18: =VLOOKUP(A18,'3月'!A:J,10,FALSE) -> 15056356955 | N18: 0 | Q18: =G18-N18 -> 0
A19: 蚌埠吾悦店邵云龙 | B19: 蚌埠吾悦店 | C19: 泳教主管 | D19: 邵云龙 | E19: 在职 | F19: 312.5 | G19: 0 | K19: 朝晖人力 | L19: =VLOOKUP(A19,[4]在职名单!$D:$AE,28,FALSE) -> 340321200111225935 | M19: =VLOOKUP(A19,[4]在职名单!$D:$AJ,33,FALSE) -> 13695528913 | Q19: =G19-N19 -> 0
A20: 蚌埠银泰店张健 | B20: 蚌埠银泰店 | C20: 店长 | D20: 张健 | E20: 在职 | F20: 1797.75 | G20: 0 | K20: 朝晖人力 | L20: =VLOOKUP(A20,'3月'!A:I,9,FALSE) -> 342601199308085099 | M20: =VLOOKUP(A20,'3月'!A:J,10,FALSE) -> 18556503671 | N20: 0 | Q20: =G20-N20 -> 0
A21: 蚌埠银泰店彭莹莹 | B21: 蚌埠银泰店 | C21: 前台主管 | D21: 彭莹莹 | E21: 在职 | F21: 1440 | G21: 0 | K21: 朝晖人力 | L21: =VLOOKUP(A21,'3月'!A:I,9,FALSE) -> 34031119930320142X | M21: =VLOOKUP(A21,'3月'!A:J,10,FALSE) -> 18895657368 | N21: 0 | Q21: =G21-N21 -> 0
A22: 蚌埠银泰店王引 | B22: 蚌埠银泰店 | C22: 前台 | D22: 王引 | E22: 在职 | F22: 1187.5 | G22: 0 | K22: 朝晖人力 | L22: =VLOOKUP(A22,'3月'!A:I,9,FALSE) -> 340311199603300024 | M22: =VLOOKUP(A22,'3月'!A:J,10,FALSE) -> 18297325069 | N22: 0 | Q22: =G22-N22 -> 0
A23: 蚌埠银泰店李桂华 | B23: 蚌埠银泰店 | C23: 保洁 | D23: 李桂华 | E23: 在职 | F23: 1150 | G23: 0 | K23: 朝晖人力 | L23: =VLOOKUP(A23,'3月'!A:I,9,FALSE) -> 340123196511187707 | M23: =VLOOKUP(A23,'3月'!A:J,10,FALSE) -> 17705522172 | N23: 0 | Q23: =G23-N23 -> 0
A24: 蚌埠银泰店王良顺 | B24: 蚌埠银泰店 | C24: 保洁 | D24: 王良顺 | E24: 在职 | F24: 1210 | G24: 0 | K24: 朝晖人力 | L24: =VLOOKUP(A24,'3月'!A:I,9,FALSE) -> 340301196210230030 | M24: =VLOOKUP(A24,'3月'!A:J,10,FALSE) -> 13965298264 | N24: 0 | Q24: =G24-N24 -> 0
A25: 蚌埠银泰店史玲娟 | B25: 蚌埠银泰店 | C25: 会籍 | D25: 史玲娟 | E25: 在职 | F25: 1440 | G25: 0 | K25: 朝晖人力 | L25: =VLOOKUP(A25,'3月'!A:I,9,FALSE) -> 340323200311216227 | M25: =VLOOKUP(A25,'3月'!A:J,10,FALSE) -> 15755212422 | N25: 0 | Q25: =G25-N25 -> 0
A26: 蚌埠银泰店邵怡 | B26: 蚌埠银泰店 | C26: 会籍 | D26: 邵怡 | E26: 在职 | F26: 270 | G26: 0 | K26: 朝晖人力 | L26: =VLOOKUP(A26,'3月'!A:I,9,FALSE) -> 340321200508126572 | M26: =VLOOKUP(A26,'3月'!A:J,10,FALSE) -> 19215600959 | N26: 0 | Q26: =G26-N26 -> 0
A27: 蚌埠银泰店王紫贵 | B27: 蚌埠银泰店 | C27: 会籍 | D27: 王紫贵 | E27: 在职 | F27: 75 | G27: 0 | K27: 朝晖人力 | L27: =VLOOKUP(A27,[4]在职名单!$D:$AE,28,FALSE) -> 340303200302060616 | M27: =VLOOKUP(A27,[4]在职名单!$D:$AJ,33,FALSE) -> 18255215140 | N27: 0 | Q27: =G27-N27 -> 0
A28: 蚌埠银泰店孙齐云 | B28: 蚌埠银泰店 | C28: 私教经理 | D28: 孙齐云 | E28: 在职 | F28: 1538.075 | G28: 0 | K28: 朝晖人力 | L28: =VLOOKUP(A28,'3月'!A:I,9,FALSE) -> 342626199407204919 | M28: =VLOOKUP(A28,'3月'!A:J,10,FALSE) -> 13851536096 | N28: 0 | Q28: =G28-N28 -> 0
A29: 蚌埠银泰店李可 | B29: 蚌埠银泰店 | C29: 私教 | D29: 李可 | E29: 在职 | F29: 270 | G29: 0 | K29: 朝晖人力 | L29: =VLOOKUP(A29,'3月'!A:I,9,FALSE) -> 340404200104240028 | M29: =VLOOKUP(A29,'3月'!A:J,10,FALSE) -> 18055464203 | N29: 0 | Q29: =G29-N29 -> 0
A30: 淮北吾悦店欧林雨 | B30: 淮北吾悦店 | C30: 前台主管 | D30: 欧林雨 | E30: 在职 | F30: 1370.53 | G30: 0 | K30: 朝晖人力 | L30: =VLOOKUP(A30,'3月'!A:I,9,FALSE) -> 342222200201195824 | M30: =VLOOKUP(A30,'3月'!A:J,10,FALSE) -> 19856101932 | N30: 0 | Q30: =G30-N30 -> 0
A31: 淮北吾悦店王紫妍 | B31: 淮北吾悦店 | C31: 前台 | D31: 王紫妍 | E31: 在职 | F31: 1174.034 | G31: 0 | K31: 朝晖人力 | L31: =VLOOKUP(A31,'3月'!A:I,9,FALSE) -> 340602200312120424 | M31: =VLOOKUP(A31,'3月'!A:J,10,FALSE) -> 17756143344 | N31: 0 | Q31: =G31-N31 -> 0
A32: 淮北吾悦店高泉 | B32: 淮北吾悦店 | C32: 保洁 | D32: 高泉 | E32: 在职 | F32: 1087.5 | G32: 0 | K32: 朝晖人力 | L32: =VLOOKUP(A32,'3月'!A:I,9,FALSE) -> 342123196308128893 | M32: =VLOOKUP(A32,'3月'!A:J,10,FALSE) -> 15156191196 | N32: 0 | Q32: =G32-N32 -> 0
A33: 淮北吾悦店王志鹏 | B33: 淮北吾悦店 | C33: 私教 | D33: 王志鹏 | E33: 在职 | F33: 104.16 | G33: 0 | K33: 朝晖人力 | L33: =VLOOKUP(A33,[4]在职名单!$D:$AE,28,FALSE) -> 340123200211201676 | M33: =VLOOKUP(A33,[4]在职名单!$D:$AJ,33,FALSE) -> 18955104181 | N33: 0 | Q33: =G33-N33 -> 0
A34: 淮南吾悦店周涛 | B34: 淮南吾悦店 | C34: 店长 | D34: 周涛 | E34: 在职 | F34: 5000.5127 | G34: 0.02 | H34: 359.84 | I34: 96.96 | J34: 13.49 | K34: =VLOOKUP(A34,'3月'!A:H,8,FALSE) -> 武汉山道 | L34: =VLOOKUP(A34,'3月'!A:I,9,FALSE) -> 421125198511060012 | M34: =VLOOKUP(A34,'3月'!A:J,10,FALSE) -> 15927100269 | N34: 0 | Q34: =G34-N34 -> 0.02
A35: 淮南吾悦店刘徐晴 | B35: 淮南吾悦店 | C35: 前台主管 | D35: 刘徐晴 | E35: 在职 | F35: 2040.5 | G35: 0 | K35: =VLOOKUP(A35,'3月'!A:H,8,FALSE) -> 朝晖人力 | L35: =VLOOKUP(A35,'3月'!A:I,9,FALSE) -> 340406199205233043 | M35: =VLOOKUP(A35,'3月'!A:J,10,FALSE) -> 17730160242 | N35: 0 | Q35: =G35-N35 -> 0
A36: 淮南吾悦店张晓冬 | B36: 淮南吾悦店 | C36: 前台 | D36: 张晓冬 | E36: 在职 | F36: 1253.25 | G36: 0 | K36: =VLOOKUP(A36,'3月'!A:H,8,FALSE) -> 朝晖人力 | L36: =VLOOKUP(A36,'3月'!A:I,9,FALSE) -> 42282519991003064X | M36: =VLOOKUP(A36,'3月'!A:J,10,FALSE) -> 15623356005 | N36: 0 | Q36: =G36-N36 -> 0
A37: 淮南吾悦店林丽 | B37: 淮南吾悦店 | C37: 保洁 | D37: 林丽 | E37: 在职 | F37: 1308 | G37: 0 | K37: =VLOOKUP(A37,'3月'!A:H,8,FALSE) -> 朝晖人力 | L37: =VLOOKUP(A37,'3月'!A:I,9,FALSE) -> 340406197002032242 | M37: =VLOOKUP(A37,'3月'!A:J,10,FALSE) -> 19855485653 | N37: 0 | Q37: =G37-N37 -> 0
A38: 淮南吾悦店许邦元 | B38: 淮南吾悦店 | C38: 保洁 | D38: 许邦元 | E38: 在职 | F38: 1417 | G38: 0 | K38: =VLOOKUP(A38,'3月'!A:H,8,FALSE) -> 朝晖人力 | L38: =VLOOKUP(A38,'3月'!A:I,9,FALSE) -> 340402196002250012 | M38: =VLOOKUP(A38,'3月'!A:J,10,FALSE) -> 15755400059 | N38: 0 | Q38: =G38-N38 -> 0
A39: 淮南吾悦店焦家喻 | B39: 淮南吾悦店 | C39: 会籍经理 | D39: 焦家喻 | E39: 在职 | F39: 1843 | G39: 0 | K39: =VLOOKUP(A39,'3月'!A:H,8,FALSE) -> 朝晖人力 | L39: =VLOOKUP(A39,'3月'!A:I,9,FALSE) -> 422326198512295217 | M39: =VLOOKUP(A39,'3月'!A:J,10,FALSE) -> 13997538150 | N39: 0 | Q39: =G39-N39 -> 0
A40: 淮南吾悦店马晨晨 | B40: 淮南吾悦店 | C40: 会籍 | D40: 马晨晨 | E40: 在职 | F40: 950 | G40: 0 | K40: =VLOOKUP(A40,'3月'!A:H,8,FALSE) -> 朝晖人力 | L40: =VLOOKUP(A40,'3月'!A:I,9,FALSE) -> 340405199309040047 | M40: =VLOOKUP(A40,'3月'!A:J,10,FALSE) -> 16605542692 | N40: 0 | Q40: =G40-N40 -> 0
...

Sheet Sheet1
A1: 116.25 | H1: 高速费 | I1: 13 | K1: 4.4 | L1: 中悦-旭辉 | M1: 61.5
A2: 531.03 | I2: 100 | K2: 4.5 | L2: 中悦到旭辉 | M2: 30.3
A3: 12 | I3: 15 | K3: 4.6 | L3: 旭辉到中悦 | M3: 54.2
A4: 15 | I4: 46 | K4: 4.6 | L4: 中悦到旭辉 | M4: 32.7
A5: 730 | I5: 16 | K5: 4.6 | L5: 旭辉-中悦 | M5: 67.6
A6: 888 | I6: 60 | K6: 4.7 | L6: 中悦到旭辉 | M6: 32.2
A7: 17.8 | H7: 聚餐 | I7: 888 | K7: 4.7 | L7: 旭辉到中悦 | M7: 32.8
A8: 16 | I8: 730 | K8: 4.7 | L8: 中悦到进贤 | M8: 80.5
A9: 46 | I9: 17.8 | K9: 4.8 | L9: 进贤-中悦 | M9: 76.5
A10: 60 | H10: 酒店 | I10: 116.25 | K10: 4.9 | L10: 中悦-旭辉 | M10: 29.4
A11: 100 | K11: 4.10号 | L11: 酒店-旭辉 | M11: 9
K12: 4.10号 | L12: 旭辉-烧烤店 | M12: 8.41
K13: 4.11 | L13: 酒店-旭辉 | M13: 8
K14: 4.12 | L14: 酒店-旭辉 | M14: 7.92
I15: =_xlfn.DISPIMG("ID_969A3F5835A64A7099550712717EFF05",1) -> =DISPIMG("ID_969A3F5835A64A7099550712717EFF05",1) | J15: =_xlfn.DISPIMG("ID_68B4BC6F35DB4AAF82D5EDA95D706E49",1) -> =DISPIMG("ID_68B4BC6F35DB4AAF82D5EDA95D706E49",1) | K15: =_xlfn.DISPIMG("ID_305D73F8981A4506B72D5FDD9B082C22",1) -> =DISPIMG("ID_305D73F8981A4506B72D5FDD9B082C22",1) | L15: =_xlfn.DISPIMG("ID_CFE543C8887E4453BEDE90128B6833DA",1) -> =DISPIMG("ID_CFE543C8887E4453BEDE90128B6833DA",1) | M15: =_xlfn.DISPIMG("ID_DC23554F1F234C87AB75F06284FA5048",1) -> =DISPIMG("ID_DC23554F1F234C87AB75F06284FA5048",1) | N15: =_xlfn.DISPIMG("ID_DD87F0FDE3ED44E4BA66B5AD88F5FF9C",1) -> =DISPIMG("ID_DD87F0FDE3ED44E4BA66B5AD88F5FF9C",1)

Sheet 5月
A1: 门店+姓名 | B1: 门店 | C1: 岗位 | D1: 姓名 | E1: 员工状态 | F1: 报税工资 | G1: 个税 | H1: 基本养老保险费 | I1: 基本医疗保险费 | J1: 失业保险费 | K1: 分公司 | L1: 身份证号 | M1: 联系方式 | N1: 实际个税 | O1: 备注 | Q1: 差额 | S1: 差额1
D2: 刘甜甜 | F2: 17000 | G2: 655.02 | H2: 1360 | I2: 347 | J2: 51 | K2: 武汉山道 | L2: 420684198505276040 | N2: 655.02 | P2: =VLOOKUP(D2,'[8]26.4'!$B:$H,7,FALSE) -> 1758 | Q2: =G2-N2 -> 0
D3: 杨艳 | F3: 2000 | H3: 359.84 | I3: 96.96 | J3: 13.49 | K3: 武汉山道 | L3: 420623198201201047 | N3: 0 | P3: =VLOOKUP(D3,'[8]26.4'!$B:$H,7,FALSE) -> 470.29 | Q3: =G3-N3 -> 0
D4: 刘建斌 | F4: 17000 | G4: 655.02 | H4: 1360 | I4: 347 | J4: 51 | K4: 武汉山道 | L4: 420684198402276056 | M4: 15927000009 | N4: 655.02 | P4: =VLOOKUP(D4,'[8]26.4'!$B:$H,7,FALSE) -> 1758 | Q4: =G4-N4 -> 0
A5: 蚌埠吾悦店王格 | B5: 蚌埠吾悦店 | C5: 前台主管 | D5: 王格 | E5: 在职 | F5: 3950 | G5: 0 | K5: =VLOOKUP(A5,'4月'!A:K,11,FALSE) -> 朝晖人力 | L5: =VLOOKUP(A5,'4月'!A:L,12,FALSE) -> 340322200502054623 | M5: =VLOOKUP(A5,'4月'!A:M,13,FALSE) -> 15375468652 | N5: 0 | Q5: =G5-N5 -> 0
A6: 蚌埠吾悦店孙颖 | B6: 蚌埠吾悦店 | C6: 前台 | D6: 孙颖 | E6: 在职 | F6: 2442 | G6: 0 | K6: =VLOOKUP(A6,'4月'!A:K,11,FALSE) -> 朝晖人力 | L6: =VLOOKUP(A6,'4月'!A:L,12,FALSE) -> 340321200212088263 | M6: =VLOOKUP(A6,'4月'!A:M,13,FALSE) -> 13155218936 | N6: 0 | Q6: =G6-N6 -> 0
A7: 蚌埠吾悦店赵红 | B7: 蚌埠吾悦店 | C7: 保洁 | D7: 赵红 | E7: 在职 | F7: 2375 | G7: 0 | K7: =VLOOKUP(A7,'4月'!A:K,11,FALSE) -> 朝晖人力 | L7: =VLOOKUP(A7,'4月'!A:L,12,FALSE) -> 340302197012310428 | M7: =VLOOKUP(A7,'4月'!A:M,13,FALSE) -> 16655298121 | N7: 0 | Q7: =G7-N7 -> 0
A8: 蚌埠吾悦店陆春亮 | B8: 蚌埠吾悦店 | C8: 保洁 | D8: 陆春亮 | E8: 在职 | F8: 2375 | G8: 0 | K8: =VLOOKUP(A8,'4月'!A:K,11,FALSE) -> 朝晖人力 | L8: =VLOOKUP(A8,'4月'!A:L,12,FALSE) -> 340302196303260411 | M8: =VLOOKUP(A8,'4月'!A:M,13,FALSE) -> 13093664952 | N8: 0 | Q8: =G8-N8 -> 0
A9: 蚌埠吾悦店万小建 | B9: 蚌埠吾悦店 | C9: 会籍经理 | D9: 万小建 | E9: 在职 | F9: 8959.02 | G9: 0 | K9: =VLOOKUP(A9,'4月'!A:K,11,FALSE) -> 朝晖人力 | L9: =VLOOKUP(A9,'4月'!A:L,12,FALSE) -> 340321198606010899 | M9: =VLOOKUP(A9,'4月'!A:M,13,FALSE) -> 1396528/6269 | N9: 0 | Q9: =G9-N9 -> 0
A10: 蚌埠吾悦店邵家文 | B10: 蚌埠吾悦店 | C10: 会籍 | D10: 邵家文 | E10: 在职 | F10: 11121.5 | G10: 0 | K10: =VLOOKUP(A10,'4月'!A:K,11,FALSE) -> 朝晖人力 | L10: =VLOOKUP(A10,'4月'!A:L,12,FALSE) -> 340321200412065031 | M10: =VLOOKUP(A10,'4月'!A:M,13,FALSE) -> 17201600134 | N10: 0 | Q10: =G10-N10 -> 0
A11: 蚌埠吾悦店赵惠春 | B11: 蚌埠吾悦店 | C11: 会籍 | D11: 赵惠春 | E11: 在职 | F11: 14344.5 | G11: 101.74 | K11: =VLOOKUP(A11,'4月'!A:K,11,FALSE) -> 朝晖人力 | L11: =VLOOKUP(A11,'4月'!A:L,12,FALSE) -> 370406200602046621 | M11: =VLOOKUP(A11,'4月'!A:M,13,FALSE) -> 19055243298 | N11: 101.74 | Q11: =G11-N11 -> 0
A12: 蚌埠吾悦店刘庆康 | B12: 蚌埠吾悦店 | C12: 会籍 | D12: 刘庆康 | E12: 在职 | F12: 1444.27 | G12: 0 | K12: =VLOOKUP(A12,'4月'!A:K,11,FALSE) -> 朝晖人力 | L12: =VLOOKUP(A12,'4月'!A:L,12,FALSE) -> 340302200512121011 | M12: =VLOOKUP(A12,[6]离职名单!$D:$T,17,FALSE) -> #N/A | N12: 0 | Q12: =G12-N12 -> 0
A13: 蚌埠吾悦店朱文娟 | B13: 蚌埠吾悦店 | C13: 会籍 | D13: 朱文娟 | E13: 离职 | F13: 979.04 | G13: 0 | K13: =VLOOKUP(A13,'4月'!A:K,11,FALSE) -> 朝晖人力 | L13: =VLOOKUP(A13,'4月'!A:L,12,FALSE) -> 340321199612088646 | M13: =VLOOKUP(A13,'4月'!A:M,13,FALSE) -> 13155218935 | N13: 0 | Q13: =G13-N13 -> 0
A14: 蚌埠吾悦店栾金良 | B14: 蚌埠吾悦店 | C14: 私教经理 | D14: 栾金良 | E14: 在职 | F14: 11461.408 | G14: 100.72 | K14: =VLOOKUP(A14,'4月'!A:K,11,FALSE) -> 朝晖人力 | L14: =VLOOKUP(A14,'4月'!A:L,12,FALSE) -> 321302198506180055 | M14: =VLOOKUP(A14,'4月'!A:M,13,FALSE) -> 13815786616 | N14: 101.17 | Q14: =G14-N14 -> -0.45
A15: 蚌埠吾悦店曲蓝鹤 | B15: 蚌埠吾悦店 | C15: 私教 | D15: 曲蓝鹤 | E15: 在职 | F15: 4290.9672 | G15: 0 | K15: =VLOOKUP(A15,'4月'!A:K,11,FALSE) -> 朝晖人力 | L15: =VLOOKUP(A15,'4月'!A:L,12,FALSE) -> 230505199011080214 | M15: =VLOOKUP(A15,'4月'!A:M,13,FALSE) -> 17755263617 | N15: 0 | Q15: =G15-N15 -> 0
A16: 蚌埠吾悦店蒋维月 | B16: 蚌埠吾悦店 | C16: 私教 | D16: 蒋维月 | E16: 在职 | F16: 4364.2517 | G16: 0 | K16: 朝晖人力 | L16: 340322200712043869 | M16: =VLOOKUP(A16,[6]在职名单!$D:$AK,34,FALSE) -> 18714837986 | N16: 0 | Q16: =G16-N16 -> 0
A17: 蚌埠吾悦店林康 | B17: 蚌埠吾悦店 | C17: 泳教主管 | D17: 林康 | E17: 在职 | F17: 7701.63 | G17: 0 | K17: =VLOOKUP(A17,'4月'!A:K,11,FALSE) -> 朝晖人力 | L17: =VLOOKUP(A17,'4月'!A:L,12,FALSE) -> 340321200212060850 | M17: =VLOOKUP(A17,'4月'!A:M,13,FALSE) -> 15056356955 | N17: 0 | Q17: =G17-N17 -> 0
A18: 蚌埠吾悦店周凯乐 | B18: 蚌埠吾悦店 | C18: 泳教 | D18: 周凯乐 | E18: 在职 | F18: 92.597407 | G18: 0 | K18: 朝晖人力 | L18: =VLOOKUP(A18,[6]在职名单!$D:$AF,29,FALSE) -> 340321200108182495 | M18: =VLOOKUP(A18,[6]在职名单!$D:$AK,34,FALSE) -> 18715261682 | N18: 0 | Q18: =G18-N18 -> 0
A19: 蚌埠吾悦店李响 | B19: 蚌埠吾悦店 | C19: 泳教 | D19: 李响 | E19: 在职 | F19: 2642.5 | G19: 0 | K19: =VLOOKUP(A19,'4月'!A:K,11,FALSE) -> 朝晖人力 | L19: =VLOOKUP(A19,'4月'!A:L,12,FALSE) -> 34030219860130002X | M19: =VLOOKUP(A19,[6]离职名单!$D:$T,17,FALSE) -> #N/A | N19: 0 | Q19: =G19-N19 -> 0
A20: 蚌埠银泰店张健 | B20: 蚌埠银泰店 | C20: 店长 | D20: 张健 | E20: 在职 | F20: 6686.792 | G20: 0 | K20: =VLOOKUP(A20,'4月'!A:K,11,FALSE) -> 朝晖人力 | L20: =VLOOKUP(A20,'4月'!A:L,12,FALSE) -> 342601199308085099 | M20: =VLOOKUP(A20,'4月'!A:M,13,FALSE) -> 18556503671 | N20: 0 | Q20: =G20-N20 -> 0
A21: 蚌埠银泰店彭莹莹 | B21: 蚌埠银泰店 | C21: 前台主管 | D21: 彭莹莹 | E21: 在职 | F21: 3450 | G21: 0 | K21: =VLOOKUP(A21,'4月'!A:K,11,FALSE) -> 朝晖人力 | L21: =VLOOKUP(A21,'4月'!A:L,12,FALSE) -> 34031119930320142X | M21: =VLOOKUP(A21,'4月'!A:M,13,FALSE) -> 18895657368 | N21: 0 | Q21: =G21-N21 -> 0
A22: 蚌埠银泰店王引 | B22: 蚌埠银泰店 | C22: 前台 | D22: 王引 | E22: 离职 | F22: 648.15 | G22: 0 | K22: =VLOOKUP(A22,'4月'!A:K,11,FALSE) -> 朝晖人力 | L22: =VLOOKUP(A22,'4月'!A:L,12,FALSE) -> 340311199603300024 | M22: =VLOOKUP(A22,'4月'!A:M,13,FALSE) -> 18297325069 | N22: 0 | Q22: =G22-N22 -> 0
A23: 蚌埠银泰店王梦蝶 | B23: 蚌埠银泰店 | C23: 前台 | D23: 王梦蝶 | E23: 在职 | F23: 2700 | G23: 0 | K23: 朝晖人力 | L23: =VLOOKUP(A23,[6]在职名单!$D:$AF,29,FALSE) -> 340321199903303123 | M23: =VLOOKUP(A23,[6]在职名单!$D:$AK,34,FALSE) -> 15021243059 | N23: 0 | Q23: =G23-N23 -> 0
A24: 蚌埠银泰店李桂华 | B24: 蚌埠银泰店 | C24: 保洁 | D24: 李桂华 | E24: 在职 | F24: 2475 | G24: 0 | K24: =VLOOKUP(A24,'4月'!A:K,11,FALSE) -> 朝晖人力 | L24: =VLOOKUP(A24,'4月'!A:L,12,FALSE) -> 340123196511187707 | M24: =VLOOKUP(A24,'4月'!A:M,13,FALSE) -> 17705522172 | N24: 0 | Q24: =G24-N24 -> 0
A25: 蚌埠银泰店王良顺 | B25: 蚌埠银泰店 | C25: 保洁 | D25: 王良顺 | E25: 在职 | F25: 2375 | G25: 0 | K25: =VLOOKUP(A25,'4月'!A:K,11,FALSE) -> 朝晖人力 | L25: =VLOOKUP(A25,'4月'!A:L,12,FALSE) -> 340301196210230030 | M25: =VLOOKUP(A25,'4月'!A:M,13,FALSE) -> 13965298264 | N25: 0 | Q25: =G25-N25 -> 0
A26: 蚌埠银泰店史玲娟 | B26: 蚌埠银泰店 | C26: 会籍 | D26: 史玲娟 | E26: 在职 | F26: 15053.316 | G26: 194.79 | K26: =VLOOKUP(A26,'4月'!A:K,11,FALSE) -> 朝晖人力 | L26: =VLOOKUP(A26,'4月'!A:L,12,FALSE) -> 340323200311216227 | M26: =VLOOKUP(A26,'4月'!A:M,13,FALSE) -> 15755212422 | N26: 194.8 | Q26: =G26-N26 -> -0.01
A27: 蚌埠银泰店邵怡 | B27: 蚌埠银泰店 | C27: 会籍 | D27: 邵怡 | E27: 离职 | F27: 31.62 | G27: 0 | K27: =VLOOKUP(A27,'4月'!A:K,11,FALSE) -> 朝晖人力 | L27: =VLOOKUP(A27,'4月'!A:L,12,FALSE) -> 340321200508126572 | M27: =VLOOKUP(A27,'4月'!A:M,13,FALSE) -> 19215600959 | N27: 0 | Q27: =G27-N27 -> 0
A28: 蚌埠银泰店王紫贵 | B28: 蚌埠银泰店 | C28: 会籍 | D28: 王紫贵 | E28: 离职 | F28: 1354.7285 | G28: 0 | K28: =VLOOKUP(A28,'4月'!A:K,11,FALSE) -> 朝晖人力 | L28: =VLOOKUP(A28,'4月'!A:L,12,FALSE) -> 340303200302060616 | M28: =VLOOKUP(A28,'4月'!A:M,13,FALSE) -> 18255215140 | N28: 0 | Q28: =G28-N28 -> 0
A29: 蚌埠银泰店顾帅帅 | B29: 蚌埠银泰店 | C29: 会籍 | D29: 顾帅帅 | E29: 离职 | F29: 2507.4026 | G29: 0 | K29: 朝晖人力 | L29: 340321200507210836 | M29: 15556190914 | N29: 0 | Q29: =G29-N29 -> 0
A30: 蚌埠银泰店马涵 | B30: 蚌埠银泰店 | C30: 会籍 | D30: 马涵 | E30: 在职 | F30: 2125.7393 | G30: 0 | K30: 朝晖人力 | L30: =VLOOKUP(A30,[6]在职名单!$D:$AF,29,FALSE) -> 340322200402200814 | M30: =VLOOKUP(A30,[6]在职名单!$D:$AK,34,FALSE) -> 18160811362 | N30: 0 | Q30: =G30-N30 -> 0
A31: 蚌埠银泰店孙齐云 | B31: 蚌埠银泰店 | C31: 私教经理 | D31: 孙齐云 | E31: 在职 | F31: 10670.64 | G31: 66.26 | K31: =VLOOKUP(A31,'4月'!A:K,11,FALSE) -> 朝晖人力 | L31: =VLOOKUP(A31,'4月'!A:L,12,FALSE) -> 342626199407204919 | M31: =VLOOKUP(A31,'4月'!A:M,13,FALSE) -> 13851536096 | N31: 66.26 | Q31: =G31-N31 -> 0
A32: 蚌埠银泰店李可 | B32: 蚌埠银泰店 | C32: 私教 | D32: 李可 | E32: 在职 | F32: 4680.5674 | G32: 0 | K32: =VLOOKUP(A32,'4月'!A:K,11,FALSE) -> 朝晖人力 | L32: =VLOOKUP(A32,'4月'!A:L,12,FALSE) -> 340404200104240028 | M32: =VLOOKUP(A32,'4月'!A:M,13,FALSE) -> 18055464203 | N32: 0 | Q32: =G32-N32 -> 0
A33: 蚌埠银泰店黄顺顺 | B33: 蚌埠银泰店 | C33: 私教 | D33: 黄顺顺 | E33: 在职 | F33: 160.004 | G33: 0 | K33: 朝晖人力 | L33: 340311200308301214 | M33: 18101221171 | N33: 0 | Q33: =G33-N33 -> 0
A34: 蚌埠银泰店黄少聪 | B34: 蚌埠银泰店 | C34: 私教 | D34: 黄少聪 | E34: 离职 | F34: 186.66867 | G34: 0 | K34: 朝晖人力 | L34: =VLOOKUP(A34,[6]在职名单!$D:$AF,29,FALSE) -> 340321200201193092 | M34: =VLOOKUP(A34,[6]在职名单!$D:$AK,34,FALSE) -> 13075571359 | O34: #N/A
A35: 蚌埠银泰店赵亮 | B35: 蚌埠银泰店 | C35: 私教 | D35: 赵亮 | E35: 离职 | F35: 373.33067 | G35: 0 | K35: 没有身份证号 | L35: 没有身份证号 | M35: 没有身份证号 | Q35: =G35-N35 -> 0
A36: 蚌埠银泰店谢震威 | B36: 蚌埠银泰店 | C36: 泳教主管 | D36: 谢震威 | E36: 在职 | F36: 4768.52 | G36: 0 | K36: 朝晖人力 | L36: =VLOOKUP(A36,[6]在职名单!$D:$AF,29,FALSE) -> 340621199808143236 | M36: =VLOOKUP(A36,[6]在职名单!$D:$AK,34,FALSE) -> 15756166520 | N36: 0 | Q36: =G36-N36 -> 0
A37: 蚌埠银泰店张磊 | B37: 蚌埠银泰店 | C37: 泳教 | D37: 张磊 | E37: 离职 | F37: 1688.15 | G37: 0 | K37: 朝晖人力 | L37: =VLOOKUP(A37,[6]在职名单!$D:$AF,29,FALSE) -> 342224199210161156 | M37: =VLOOKUP(A37,[6]在职名单!$D:$AK,34,FALSE) -> 15262349964 | N37: 0 | Q37: =G37-N37 -> 0
A38: 蚌埠银泰店王宇恒 | B38: 蚌埠银泰店 | C38: 泳教 | D38: 王宇恒 | E38: 离职 | F38: 3165.54 | G38: 0 | K38: 朝晖人力 | L38: =VLOOKUP(A38,[6]在职名单!$D:$AF,29,FALSE) -> 340321200206273438 | M38: =VLOOKUP(A38,[6]在职名单!$D:$AK,34,FALSE) -> 18155415334 | N38: 0 | Q38: =G38-N38 -> 0
A39: 蚌埠银泰店张建成 | B39: 蚌埠银泰店 | C39: 泳教 | D39: 张建成 | E39: 在职 | F39: 325.92963 | G39: 0 | K39: 朝晖人力 | L39: 340323199705206253 | M39: 15155203756 | N39: 0 | Q39: =G39-N39 -> 0
A40: 蚌埠银泰店高传宏 | B40: 蚌埠银泰店 | C40: 救生员 | D40: 高传宏 | E40: 在职 | F40: 2214.81 | G40: 0 | K40: 朝晖人力 | L40: =VLOOKUP(A40,[6]在职名单!$D:$AF,29,FALSE) -> 340304196904170633 | M40: =VLOOKUP(A40,[6]在职名单!$D:$AK,34,FALSE) -> 13295524310 | N40: 0 | Q40: =G40-N40 -> 0
...

Sheet 6月
A1: 门店+姓名 | B1: 门店 | C1: 岗位 | D1: 姓名 | E1: 员工状态 | F1: 报税工资 | G1: 个税 | H1: 基本养老保险费 | I1: 基本医疗保险费 | J1: 失业保险费 | K1: 分公司 | L1: 身份证号 | M1: 联系方式 | N1: 实际个税 | O1: 备注 | Q1: 差额 | S1: 差额1
D2: 刘甜甜 | F2: 17000 | G2: 1024.2 | H2: 1360 | I2: 347 | J2: 51 | K2: 武汉山道 | L2: 420684198505276040 | N2: 1024.2 | Q2: =G2-N2 -> 0
D3: 杨艳 | F3: 2000 | H3: 359.84 | I3: 96.96 | J3: 13.49 | K3: 武汉山道 | L3: 420623198201201047 | N3: 0 | Q3: =G3-N3 -> 0
D4: 刘建斌 | F4: 17000 | G4: 1024.2 | H4: 1360 | I4: 347 | J4: 51 | K4: 武汉山道 | L4: 420684198402276056 | M4: 15927000009 | N4: 1024.2 | Q4: =G4-N4 -> 0
A5: 蚌埠吾悦店王格 | B5: 蚌埠吾悦店 | C5: 前台 | D5: 王格 | E5: 在职 | F5: 4000 | G5: 0 | K5: =VLOOKUP(A5,'5月'!A:K,11,FALSE) -> 朝晖人力 | L5: =VLOOKUP(A5,'5月'!A:L,12,FALSE) -> 340322200502054623 | M5: =VLOOKUP(A5,'5月'!A:M,13,FALSE) -> 15375468652 | N5: =VLOOKUP(D5,[11]个人所得税扣缴申报表!$B$1:$L$65536,11,FALSE) -> 0 | Q5: =G5-N5 -> 0
A6: 蚌埠吾悦店孙颖 | B6: 蚌埠吾悦店 | C6: 前台 | D6: 孙颖 | E6: 在职 | F6: 2460 | G6: 0 | K6: =VLOOKUP(A6,'5月'!A:K,11,FALSE) -> 朝晖人力 | L6: =VLOOKUP(A6,'5月'!A:L,12,FALSE) -> 340321200212088263 | M6: =VLOOKUP(A6,'5月'!A:M,13,FALSE) -> 13155218936 | N6: =VLOOKUP(D6,[11]个人所得税扣缴申报表!$B$1:$L$65536,11,FALSE) -> 0 | Q6: =G6-N6 -> 0
A7: 蚌埠吾悦店赵红 | B7: 蚌埠吾悦店 | C7: 保洁 | D7: 赵红 | E7: 在职 | F7: 2375 | G7: 0 | K7: =VLOOKUP(A7,'5月'!A:K,11,FALSE) -> 朝晖人力 | L7: =VLOOKUP(A7,'5月'!A:L,12,FALSE) -> 340302197012310428 | M7: =VLOOKUP(A7,'5月'!A:M,13,FALSE) -> 16655298121 | N7: =VLOOKUP(D7,[11]个人所得税扣缴申报表!$B$1:$L$65536,11,FALSE) -> 0 | Q7: =G7-N7 -> 0
A8: 蚌埠吾悦店陆春亮 | B8: 蚌埠吾悦店 | C8: 保洁 | D8: 陆春亮 | E8: 在职 | F8: 2375 | G8: 0 | K8: =VLOOKUP(A8,'5月'!A:K,11,FALSE) -> 朝晖人力 | L8: =VLOOKUP(A8,'5月'!A:L,12,FALSE) -> 340302196303260411 | M8: =VLOOKUP(A8,'5月'!A:M,13,FALSE) -> 13093664952 | N8: =VLOOKUP(D8,[11]个人所得税扣缴申报表!$B$1:$L$65536,11,FALSE) -> 0 | Q8: =G8-N8 -> 0
A9: 蚌埠吾悦店万小建 | B9: 蚌埠吾悦店 | C9: 会籍经理 | D9: 万小建 | E9: 在职 | F9: 6202.0295 | G9: 30.73 | K9: =VLOOKUP(A9,'5月'!A:K,11,FALSE) -> 朝晖人力 | L9: =VLOOKUP(A9,'5月'!A:L,12,FALSE) -> 340321198606010899 | M9: =VLOOKUP(A9,'5月'!A:M,13,FALSE) -> 1396528/6269 | N9: =VLOOKUP(D9,[11]个人所得税扣缴申报表!$B$1:$L$65536,11,FALSE) -> 30.73 | Q9: =G9-N9 -> 0
A10: 蚌埠吾悦店邵家文 | B10: 蚌埠吾悦店 | C10: 会籍 | D10: 邵家文 | E10: 在职 | F10: 3672.45 | G10: 0 | K10: =VLOOKUP(A10,'5月'!A:K,11,FALSE) -> 朝晖人力 | L10: =VLOOKUP(A10,'5月'!A:L,12,FALSE) -> 340321200412065031 | M10: =VLOOKUP(A10,'5月'!A:M,13,FALSE) -> 17201600134 | N10: =VLOOKUP(D10,[11]个人所得税扣缴申报表!$B$1:$L$65536,11,FALSE) -> 0 | Q10: =G10-N10 -> 0
A11: 蚌埠吾悦店赵惠春 | B11: 蚌埠吾悦店 | C11: 会籍 | D11: 赵惠春 | E11: 在职 | F11: 5050.76 | G11: 1.52 | K11: =VLOOKUP(A11,'5月'!A:K,11,FALSE) -> 朝晖人力 | L11: =VLOOKUP(A11,'5月'!A:L,12,FALSE) -> 370406200602046621 | M11: =VLOOKUP(A11,'5月'!A:M,13,FALSE) -> 19055243298 | N11: =VLOOKUP(D11,[11]个人所得税扣缴申报表!$B$1:$L$65536,11,FALSE) -> 1.52 | Q11: 0
A12: 蚌埠吾悦店刘庆康 | B12: 蚌埠吾悦店 | C12: 会籍 | D12: 刘庆康 | E12: 在职 | F12: 1514.36 | G12: 0 | K12: =VLOOKUP(A12,'5月'!A:K,11,FALSE) -> 朝晖人力 | L12: =VLOOKUP(A12,'5月'!A:L,12,FALSE) -> 340302200512121011 | M12: =VLOOKUP(A12,'5月'!A:M,13,FALSE) -> #N/A | N12: =VLOOKUP(D12,[11]个人所得税扣缴申报表!$B$1:$L$65536,11,FALSE) -> 0 | Q12: =G12-N12 -> 0
A13: 蚌埠吾悦店曹泽 | B13: 蚌埠吾悦店 | C13: 会籍 | D13: 曹泽 | E13: 在职 | F13: 1858.94 | G13: 0 | K13: 朝晖人力 | L13: =VLOOKUP(A13,[10]在职名单!$D:$AF,29,FALSE) -> 340323200404246919 | M13: =VLOOKUP(A13,[10]在职名单!$D:$AK,34,FALSE) -> 19556139314 | N13: =VLOOKUP(D13,[11]个人所得税扣缴申报表!$B$1:$L$65536,11,FALSE) -> 0 | Q13: =G13-N13 -> 0
A14: 蚌埠吾悦店栾金良 | B14: 蚌埠吾悦店 | C14: 私教经理 | D14: 栾金良 | E14: 在职 | F14: 7913.725 | G14: 87.41 | K14: =VLOOKUP(A14,'5月'!A:K,11,FALSE) -> 朝晖人力 | L14: =VLOOKUP(A14,'5月'!A:L,12,FALSE) -> 321302198506180055 | M14: =VLOOKUP(A14,'5月'!A:M,13,FALSE) -> 13815786616 | N14: =VLOOKUP(D14,[11]个人所得税扣缴申报表!$B$1:$L$65536,11,FALSE) -> 87.41 | Q14: =G14-N14 -> 0
A15: 蚌埠吾悦店曲蓝鹤 | B15: 蚌埠吾悦店 | C15: 私教 | D15: 曲蓝鹤 | E15: 在职 | F15: 4430.4903 | G15: 0 | K15: =VLOOKUP(A15,'5月'!A:K,11,FALSE) -> 朝晖人力 | L15: =VLOOKUP(A15,'5月'!A:L,12,FALSE) -> 230505199011080214 | M15: =VLOOKUP(A15,'5月'!A:M,13,FALSE) -> 17755263617 | N15: =VLOOKUP(D15,[11]个人所得税扣缴申报表!$B$1:$L$65536,11,FALSE) -> 0 | Q15: =G15-N15 -> 0
A16: 蚌埠吾悦店蒋维月 | B16: 蚌埠吾悦店 | C16: 私教 | D16: 蒋维月 | E16: 在职 | F16: 1643.1468 | G16: 0 | K16: =VLOOKUP(A16,'5月'!A:K,11,FALSE) -> 朝晖人力 | L16: =VLOOKUP(A16,'5月'!A:L,12,FALSE) -> 340322200712043869 | M16: =VLOOKUP(A16,'5月'!A:M,13,FALSE) -> 18714837986 | N16: =VLOOKUP(D16,[11]个人所得税扣缴申报表!$B$1:$L$65536,11,FALSE) -> 0 | Q16: =G16-N16 -> 0
A17: 蚌埠吾悦店林康 | B17: 蚌埠吾悦店 | C17: 泳教主管 | D17: 林康 | E17: 在职 | F17: 6644.631 | G17: 0 | K17: =VLOOKUP(A17,'5月'!A:K,11,FALSE) -> 朝晖人力 | L17: =VLOOKUP(A17,'5月'!A:L,12,FALSE) -> 340321200212060850 | M17: =VLOOKUP(A17,'5月'!A:M,13,FALSE) -> 15056356955 | N17: =VLOOKUP(D17,[11]个人所得税扣缴申报表!$B$1:$L$65536,11,FALSE) -> 0 | Q17: =G17-N17 -> 0
A18: 蚌埠吾悦店周凯乐 | B18: 蚌埠吾悦店 | C18: 泳教 | D18: 周凯乐 | E18: 在职 | F18: 3515.77 | G18: 0 | K18: =VLOOKUP(A18,'5月'!A:K,11,FALSE) -> 朝晖人力 | L18: =VLOOKUP(A18,'5月'!A:L,12,FALSE) -> 340321200108182495 | M18: =VLOOKUP(A18,'5月'!A:M,13,FALSE) -> 18715261682 | N18: =VLOOKUP(D18,[11]个人所得税扣缴申报表!$B$1:$L$65536,11,FALSE) -> 0 | Q18: =G18-N18 -> 0
A19: 蚌埠吾悦店李响 | B19: 蚌埠吾悦店 | C19: 泳教 | D19: 李响 | E19: 兼职 | F19: 1739.5 | G19: 0 | K19: =VLOOKUP(A19,'5月'!A:K,11,FALSE) -> 朝晖人力 | L19: =VLOOKUP(A19,'5月'!A:L,12,FALSE) -> 34030219860130002X | M19: =VLOOKUP(A19,'5月'!A:M,13,FALSE) -> #N/A | N19: =VLOOKUP(D19,[11]个人所得税扣缴申报表!$B$1:$L$65536,11,FALSE) -> 0 | Q19: =G19-N19 -> 0
A20: 蚌埠吾悦店朱家安 | B20: 蚌埠吾悦店 | C20: 泳教 | D20: 朱家安 | E20: 离职 | F20: 1300 | G20: 0 | K20: 朝晖人力 | L20: 340621200301190813 | M20: =VLOOKUP(A20,[10]在职名单!$D:$AK,34,FALSE) -> 18656140985 | N20: =VLOOKUP(D20,[11]个人所得税扣缴申报表!$B$1:$L$65536,11,FALSE) -> 0 | Q20: =G20-N20 -> 0
A21: 蚌埠吾悦店王欣悦 | B21: 蚌埠吾悦店 | C21: 泳教 | D21: 王欣悦 | E21: 在职 | F21: 800 | G21: 0 | K21: 朝晖人力 | L21: =VLOOKUP(A21,[10]在职名单!$D:$AF,29,FALSE) -> 34030220050401024x | M21: =VLOOKUP(A21,[10]在职名单!$D:$AK,34,FALSE) -> 17201602086 | N21: =VLOOKUP(D21,[11]个人所得税扣缴申报表!$B$1:$L$65536,11,FALSE) -> 0 | Q21: =G21-N21 -> 0
A22: 蚌埠银泰店张健 | B22: 蚌埠银泰店 | C22: 店长 | D22: 张健 | E22: 离职 | F22: 6693.035 | G22: 5.33 | K22: =VLOOKUP(A22,'5月'!A:K,11,FALSE) -> 朝晖人力 | L22: =VLOOKUP(A22,'5月'!A:L,12,FALSE) -> 342601199308085099 | M22: =VLOOKUP(A22,'5月'!A:M,13,FALSE) -> 18556503671 | N22: =VLOOKUP(D22,[11]个人所得税扣缴申报表!$B$1:$L$65536,11,FALSE) -> 5.33 | Q22: =G22-N22 -> 0
A23: 蚌埠银泰店彭莹莹 | B23: 蚌埠银泰店 | C23: 前台主管 | D23: 彭莹莹 | E23: 在职 | F23: 3460 | G23: 0 | K23: =VLOOKUP(A23,'5月'!A:K,11,FALSE) -> 朝晖人力 | L23: =VLOOKUP(A23,'5月'!A:L,12,FALSE) -> 34031119930320142X | M23: =VLOOKUP(A23,'5月'!A:M,13,FALSE) -> 18895657368 | N23: =VLOOKUP(D23,[11]个人所得税扣缴申报表!$B$1:$L$65536,11,FALSE) -> 0 | Q23: =G23-N23 -> 0
A24: 蚌埠银泰店王梦蝶 | B24: 蚌埠银泰店 | C24: 前台 | D24: 王梦蝶 | E24: 在职 | F24: 2660 | G24: 0 | K24: =VLOOKUP(A24,'5月'!A:K,11,FALSE) -> 朝晖人力 | L24: =VLOOKUP(A24,'5月'!A:L,12,FALSE) -> 340321199903303123 | M24: =VLOOKUP(A24,'5月'!A:M,13,FALSE) -> 15021243059 | N24: =VLOOKUP(D24,[11]个人所得税扣缴申报表!$B$1:$L$65536,11,FALSE) -> 0 | Q24: =G24-N24 -> 0
A25: 蚌埠银泰店李桂华 | B25: 蚌埠银泰店 | C25: 保洁 | D25: 李桂华 | E25: 在职 | F25: 2450 | G25: 0 | K25: =VLOOKUP(A25,'5月'!A:K,11,FALSE) -> 朝晖人力 | L25: =VLOOKUP(A25,'5月'!A:L,12,FALSE) -> 340123196511187707 | M25: =VLOOKUP(A25,'5月'!A:M,13,FALSE) -> 17705522172 | N25: =VLOOKUP(D25,[11]个人所得税扣缴申报表!$B$1:$L$65536,11,FALSE) -> 0 | Q25: =G25-N25 -> 0
A26: 蚌埠银泰店王良顺 | B26: 蚌埠银泰店 | C26: 保洁 | D26: 王良顺 | E26: 离职 | F26: 2325 | G26: 0 | K26: =VLOOKUP(A26,'5月'!A:K,11,FALSE) -> 朝晖人力 | L26: =VLOOKUP(A26,'5月'!A:L,12,FALSE) -> 340301196210230030 | M26: =VLOOKUP(A26,'5月'!A:M,13,FALSE) -> 13965298264 | N26: =VLOOKUP(D26,[11]个人所得税扣缴申报表!$B$1:$L$65536,11,FALSE) -> 0 | Q26: =G26-N26 -> 0
A27: 蚌埠银泰店史玲娟 | B27: 蚌埠银泰店 | C27: 会籍 | D27: 史玲娟 | E27: 在职 | F27: 4987.86 | G27: 0 | K27: =VLOOKUP(A27,'5月'!A:K,11,FALSE) -> 朝晖人力 | L27: =VLOOKUP(A27,'5月'!A:L,12,FALSE) -> 340323200311216227 | M27: =VLOOKUP(A27,'5月'!A:M,13,FALSE) -> 15755212422 | N27: =VLOOKUP(D27,[11]个人所得税扣缴申报表!$B$1:$L$65536,11,FALSE) -> 0 | Q27: =G27-N27 -> 0
A28: 蚌埠银泰店张鑫杰 | B28: 蚌埠银泰店 | C28: 会籍 | D28: 张鑫杰 | E28: 离职 | F28: 2461.5 | G28: 0 | K28: 朝晖人力 | L28: =VLOOKUP(A28,[10]在职名单!$D:$AF,29,FALSE) -> 410221200502176512 | M28: =VLOOKUP(A28,[10]在职名单!$D:$AK,34,FALSE) -> 18836866156 | N28: =VLOOKUP(D28,[11]个人所得税扣缴申报表!$B$1:$L$65536,11,FALSE) -> 0 | Q28: =G28-N28 -> 0
A29: 蚌埠银泰店孙齐云 | B29: 蚌埠银泰店 | C29: 私教经理 | D29: 孙齐云 | E29: 在职 | F29: 8207.0795 | G29: 96.22 | K29: =VLOOKUP(A29,'5月'!A:K,11,FALSE) -> 朝晖人力 | L29: =VLOOKUP(A29,'5月'!A:L,12,FALSE) -> 342626199407204919 | M29: =VLOOKUP(A29,'5月'!A:M,13,FALSE) -> 13851536096 | N29: =VLOOKUP(D29,[11]个人所得税扣缴申报表!$B$1:$L$65536,11,FALSE) -> 96.22 | Q29: =G29-N29 -> 0
A30: 蚌埠银泰店李可 | B30: 蚌埠银泰店 | C30: 私教 | D30: 李可 | E30: 在职 | F30: 3943.4178 | G30: 0 | K30: =VLOOKUP(A30,'5月'!A:K,11,FALSE) -> 朝晖人力 | L30: =VLOOKUP(A30,'5月'!A:L,12,FALSE) -> 340404200104240028 | M30: =VLOOKUP(A30,'5月'!A:M,13,FALSE) -> 18055464203 | N30: =VLOOKUP(D30,[11]个人所得税扣缴申报表!$B$1:$L$65536,11,FALSE) -> 0 | Q30: =G30-N30 -> 0
A31: 蚌埠银泰店黄顺顺 | B31: 蚌埠银泰店 | C31: 私教 | D31: 黄顺顺 | E31: 在职 | F31: 3142.562 | G31: 0 | K31: =VLOOKUP(A31,'5月'!A:K,11,FALSE) -> 朝晖人力 | L31: =VLOOKUP(A31,'5月'!A:L,12,FALSE) -> 340311200308301214 | M31: =VLOOKUP(A31,'5月'!A:M,13,FALSE) -> 18101221171 | N31: =VLOOKUP(D31,[11]个人所得税扣缴申报表!$B$1:$L$65536,11,FALSE) -> 0 | Q31: =G31-N31 -> 0
A32: 蚌埠银泰店顾帅帅 | B32: 蚌埠银泰店 | C32: 私教 | D32: 顾帅帅 | E32: 离职 | F32: 820.28571 | G32: 0 | K32: =VLOOKUP(A32,'5月'!A:K,11,FALSE) -> 朝晖人力 | L32: =VLOOKUP(A32,'5月'!A:L,12,FALSE) -> 340321200507210836 | M32: =VLOOKUP(A32,'5月'!A:M,13,FALSE) -> 15556190914 | N32: =VLOOKUP(D32,[11]个人所得税扣缴申报表!$B$1:$L$65536,11,FALSE) -> 0 | Q32: =G32-N32 -> 0
